package mods.polyblockz.common.blocks.constructions;

import ibxm.Player;

import java.util.Random;

import mods.polyblockz.common.PolyBlockz;
import mods.polyblockz.common.main.Block_Helper;
import net.minecraft.block.Block;
import net.minecraft.world.World;
import net.minecraft.world.gen.feature.WorldGenerator;
import net.minecraft.world.gen.structure.StructureBoundingBox;

public class BlokkHouse_hidingplace extends WorldGenerator {

	public boolean generate(World world, Random par2Random, int i,
			int j, int k) {


		if (world.getBlockId(i, j, k) == Block_Helper.BlokkHouse_hidingplace.blockID) {
			
			/*
			 * Blokk House
			 */

			
			world.setBlock(i + 0, j + 0, k + 0, Block.cobblestone.blockID);
			world.setBlock(i + 0, j + 0, k + 1, Block.cobblestone.blockID);
			world.setBlock(i + 0, j + 0, k + 2, Block.cobblestone.blockID);
			world.setBlock(i + 0, j + 0, k + 3, Block.cobblestone.blockID);
			world.setBlock(i + 0, j + 0, k + 4, Block.cobblestone.blockID);
			world.setBlock(i + 0, j + 0, k + 5, Block.cobblestone.blockID);
			world.setBlock(i + 0, j + 0, k + 6, Block.cobblestone.blockID);
			world.setBlock(i + 0, j + 0, k + 7, Block.cobblestone.blockID);
			world.setBlock(i + 0, j + 0, k + 8, Block.cobblestone.blockID);
			world.setBlock(i + 0, j + 0, k + 9, Block.cobblestone.blockID);
			world.setBlock(i + 0, j + 0, k + 10, Block.cobblestone.blockID);
			world.setBlock(i + 0, j + 1, k + 0, Block.cobblestone.blockID);
			world.setBlock(i + 0, j + 1, k + 1, Block.cobblestone.blockID);
			world.setBlock(i + 0, j + 1, k + 2, Block.cobblestone.blockID);
			world.setBlock(i + 0, j + 1, k + 3, Block.cobblestone.blockID);
			world.setBlock(i + 0, j + 1, k + 4, Block.cobblestone.blockID);
			world.setBlock(i + 0, j + 1, k + 5, Block.cobblestone.blockID);
			world.setBlock(i + 0, j + 1, k + 6, Block.cobblestone.blockID);
			world.setBlock(i + 0, j + 1, k + 7, Block.cobblestone.blockID);
			world.setBlock(i + 0, j + 1, k + 8, Block.cobblestone.blockID);
			world.setBlock(i + 0, j + 1, k + 9, Block.cobblestone.blockID);
			world.setBlock(i + 0, j + 1, k + 10, Block.cobblestone.blockID);
			world.setBlock(i + 0, j + 2, k + 0, Block.cobblestone.blockID);
			world.setBlock(i + 0, j + 2, k + 1, Block.cobblestone.blockID);
			world.setBlock(i + 0, j + 2, k + 2, Block.cobblestone.blockID);
			world.setBlock(i + 0, j + 2, k + 3, Block.cobblestone.blockID);
			world.setBlock(i + 0, j + 2, k + 4, Block.cobblestone.blockID);
			world.setBlock(i + 0, j + 2, k + 5, Block.cobblestone.blockID);
			world.setBlock(i + 0, j + 2, k + 6, Block.cobblestone.blockID);
			world.setBlock(i + 0, j + 2, k + 7, Block.cobblestone.blockID);
			world.setBlock(i + 0, j + 2, k + 8, Block.cobblestone.blockID);
			world.setBlock(i + 0, j + 2, k + 9, Block.cobblestone.blockID);
			world.setBlock(i + 0, j + 2, k + 10, Block.cobblestone.blockID);
			world.setBlock(i + 0, j + 3, k + 0, Block.cobblestone.blockID);
			world.setBlock(i + 0, j + 3, k + 1, Block.cobblestone.blockID);
			world.setBlock(i + 0, j + 3, k + 2, Block.cobblestone.blockID);
			world.setBlock(i + 0, j + 3, k + 3, Block.cobblestone.blockID);
			world.setBlock(i + 0, j + 3, k + 4, Block.cobblestone.blockID);
			world.setBlock(i + 0, j + 3, k + 5, Block.cobblestone.blockID);
			world.setBlock(i + 0, j + 3, k + 6, Block.cobblestone.blockID);
			world.setBlock(i + 0, j + 3, k + 7, Block.cobblestone.blockID);
			world.setBlock(i + 0, j + 3, k + 8, Block.cobblestone.blockID);
			world.setBlock(i + 0, j + 3, k + 9, Block.cobblestone.blockID);
			world.setBlock(i + 0, j + 3, k + 10, Block.cobblestone.blockID);
			world.setBlock(i + 0, j + 4, k + 0, Block.cobblestone.blockID);
			world.setBlock(i + 0, j + 4, k + 1, Block.cobblestone.blockID);
			world.setBlock(i + 0, j + 4, k + 2, Block.cobblestone.blockID);
			world.setBlock(i + 0, j + 4, k + 3, Block.cobblestone.blockID);
			world.setBlock(i + 0, j + 4, k + 4, Block.cobblestone.blockID);
			world.setBlock(i + 0, j + 4, k + 5, Block.cobblestone.blockID);
			world.setBlock(i + 0, j + 4, k + 6, Block.cobblestone.blockID);
			world.setBlock(i + 0, j + 4, k + 7, Block.cobblestone.blockID);
			world.setBlock(i + 0, j + 4, k + 8, Block.cobblestone.blockID);
			world.setBlock(i + 0, j + 4, k + 9, Block.cobblestone.blockID);
			world.setBlock(i + 0, j + 4, k + 10, Block.cobblestone.blockID);
			world.setBlock(i + 1, j + 0, k + 0, Block.cobblestone.blockID);
			world.setBlock(i + 1, j + 0, k + 1, Block.stoneDoubleSlab.blockID);
			world.setBlock(i + 1, j + 0, k + 2, Block.planks.blockID);
			world.setBlock(i + 1, j + 0, k + 3, Block.planks.blockID);
			world.setBlock(i + 1, j + 0, k + 4, Block.planks.blockID);
			world.setBlock(i + 1, j + 0, k + 5, Block.planks.blockID);
			world.setBlock(i + 1, j + 0, k + 6, Block.planks.blockID);
			world.setBlock(i + 1, j + 0, k + 7, Block.planks.blockID);
			world.setBlock(i + 1, j + 0, k + 8, Block.planks.blockID);
			world.setBlock(i + 1, j + 0, k + 9, Block.planks.blockID);
			world.setBlock(i + 1, j + 0, k + 10, Block.cobblestone.blockID);
			world.setBlock(i + 1, j + 1, k + 0, Block.cobblestone.blockID);
			world.setBlock(i + 1, j + 1, k + 1, Block.stoneDoubleSlab.blockID);
			world.setBlock(i + 1, j + 1, k + 2, 0);
			world.setBlock(i + 1, j + 1, k + 3, 0);
			world.setBlock(i + 1, j + 1, k + 4, 0);
			world.setBlock(i + 1, j + 1, k + 5, 0);
			world.setBlock(i + 1, j + 1, k + 6, 0);
			world.setBlock(i + 1, j + 1, k + 7, 0);
			world.setBlock(i + 1, j + 1, k + 8, 0);
			world.setBlock(i + 1, j + 1, k + 9, 0);
			world.setBlock(i + 1, j + 1, k + 10, Block.cobblestone.blockID);
			world.setBlock(i + 1, j + 2, k + 0, Block.cobblestone.blockID);
			world.setBlock(i + 1, j + 2, k + 1, Block.stoneDoubleSlab.blockID);
			world.setBlock(i + 1, j + 2, k + 2, 0);
			world.setBlock(i + 1, j + 2, k + 3, 0);
			world.setBlock(i + 1, j + 2, k + 4, 0);
			world.setBlock(i + 1, j + 2, k + 5, 0);
			world.setBlock(i + 1, j + 2, k + 6, 0);
			world.setBlock(i + 1, j + 2, k + 7, 0);
			world.setBlock(i + 1, j + 2, k + 8, 0);
			world.setBlock(i + 1, j + 2, k + 9, 0);
			world.setBlock(i + 1, j + 2, k + 10, Block.cobblestone.blockID);
			world.setBlock(i + 1, j + 3, k + 0, Block.cobblestone.blockID);
			world.setBlock(i + 1, j + 3, k + 1, Block.stoneDoubleSlab.blockID);
			world.setBlock(i + 1, j + 3, k + 2, 0);
			world.setBlock(i + 1, j + 3, k + 3, 0);
			world.setBlock(i + 1, j + 3, k + 4, 0);
			world.setBlock(i + 1, j + 3, k + 5, 0);
			world.setBlock(i + 1, j + 3, k + 6, 0);
			world.setBlock(i + 1, j + 3, k + 7, 0);
			world.setBlock(i + 1, j + 3, k + 8, 0);
			world.setBlock(i + 1, j + 3, k + 9, 0);
			world.setBlock(i + 1, j + 3, k + 10, Block.cobblestone.blockID);
			world.setBlock(i + 1, j + 4, k + 0, Block.cobblestone.blockID);
			world.setBlock(i + 1, j + 4, k + 1, Block.stoneDoubleSlab.blockID);
			world.setBlock(i + 1, j + 4, k + 2, Block.glowStone.blockID);
			world.setBlock(i + 1, j + 4, k + 3, Block.planks.blockID);
			world.setBlock(i + 1, j + 4, k + 4, Block.planks.blockID);
			world.setBlock(i + 1, j + 4, k + 5, Block.planks.blockID);
			world.setBlock(i + 1, j + 4, k + 6, Block.planks.blockID);
			world.setBlock(i + 1, j + 4, k + 7, Block.planks.blockID);
			world.setBlock(i + 1, j + 4, k + 8, Block.glowStone.blockID);
			world.setBlock(i + 1, j + 4, k + 9, Block.cobblestone.blockID);
			world.setBlock(i + 1, j + 4, k + 10, Block.cobblestone.blockID);
			world.setBlock(i + 2, j + 0, k + 0, Block.cobblestone.blockID);
			world.setBlock(i + 2, j + 0, k + 1, Block.stoneDoubleSlab.blockID);
			world.setBlock(i + 2, j + 0, k + 2, Block.planks.blockID);
			world.setBlock(i + 2, j + 0, k + 3, Block.planks.blockID);
			world.setBlock(i + 2, j + 0, k + 4, Block.planks.blockID);
			world.setBlock(i + 2, j + 0, k + 5, Block.planks.blockID);
			world.setBlock(i + 2, j + 0, k + 6, Block.planks.blockID);
			world.setBlock(i + 2, j + 0, k + 7, Block.planks.blockID);
			world.setBlock(i + 2, j + 0, k + 8, Block.planks.blockID);
			world.setBlock(i + 2, j + 0, k + 9, Block.planks.blockID);
			world.setBlock(i + 2, j + 0, k + 10, Block.cobblestone.blockID);
			world.setBlock(i + 2, j + 1, k + 0, Block.cobblestone.blockID);
			world.setBlock(i + 2, j + 1, k + 1, Block.chest.blockID);
			world.setBlock(i + 2, j + 1, k + 2, 0);
			world.setBlock(i + 2, j + 1, k + 3, 0);
			world.setBlock(i + 2, j + 1, k + 4, 0);
			world.setBlock(i + 2, j + 1, k + 5, 0);
			world.setBlock(i + 2, j + 1, k + 6, 0);
			world.setBlock(i + 2, j + 1, k + 7, 0);
			world.setBlock(i + 2, j + 1, k + 8, 0);
			world.setBlock(i + 2, j + 1, k + 9, 0);
			world.setBlock(i + 2, j + 1, k + 10, Block.cobblestone.blockID);
			world.setBlock(i + 2, j + 2, k + 0, Block.cobblestone.blockID);
			world.setBlock(i + 2, j + 2, k + 1, Block.chest.blockID);
			world.setBlock(i + 2, j + 2, k + 2, 0);
			world.setBlock(i + 2, j + 2, k + 3, 0);
			world.setBlock(i + 2, j + 2, k + 4, 0);
			world.setBlock(i + 2, j + 2, k + 5, 0);
			world.setBlock(i + 2, j + 2, k + 6, 0);
			world.setBlock(i + 2, j + 2, k + 7, 0);
			world.setBlock(i + 2, j + 2, k + 8, 0);
			world.setBlock(i + 2, j + 2, k + 9, 0);
			world.setBlock(i + 2, j + 2, k + 10, Block.cobblestone.blockID);
			world.setBlock(i + 2, j + 3, k + 0, Block.cobblestone.blockID);
			world.setBlock(i + 2, j + 3, k + 1, Block.chest.blockID);
			world.setBlock(i + 2, j + 3, k + 2, 0);
			world.setBlock(i + 2, j + 3, k + 3, 0);
			world.setBlock(i + 2, j + 3, k + 4, 0);
			world.setBlock(i + 2, j + 3, k + 5, 0);
			world.setBlock(i + 2, j + 3, k + 6, 0);
			world.setBlock(i + 2, j + 3, k + 7, 0);
			world.setBlock(i + 2, j + 3, k + 8, 0);
			world.setBlock(i + 2, j + 3, k + 9, 0);
			world.setBlock(i + 2, j + 3, k + 10, Block.cobblestone.blockID);
			world.setBlock(i + 2, j + 4, k + 0, Block.cobblestone.blockID);
			world.setBlock(i + 2, j + 4, k + 1, Block.stoneSingleSlab.blockID);
			world.setBlock(i + 2, j + 4, k + 2, Block.planks.blockID);
			world.setBlock(i + 2, j + 4, k + 3, Block.planks.blockID);
			world.setBlock(i + 2, j + 4, k + 4, Block.planks.blockID);
			world.setBlock(i + 2, j + 4, k + 5, Block.planks.blockID);
			world.setBlock(i + 2, j + 4, k + 6, Block.planks.blockID);
			world.setBlock(i + 2, j + 4, k + 7, Block.planks.blockID);
			world.setBlock(i + 2, j + 4, k + 8, Block.planks.blockID);
			world.setBlock(i + 2, j + 4, k + 9, Block.cobblestone.blockID);
			world.setBlock(i + 2, j + 4, k + 10, Block.cobblestone.blockID);
			world.setBlock(i + 3, j + 0, k + 0, Block.cobblestone.blockID);
			world.setBlock(i + 3, j + 0, k + 1, Block.stoneDoubleSlab.blockID);
			world.setBlock(i + 3, j + 0, k + 2, Block.planks.blockID);
			world.setBlock(i + 3, j + 0, k + 3, Block.planks.blockID);
			world.setBlock(i + 3, j + 0, k + 4, Block.planks.blockID);
			world.setBlock(i + 3, j + 0, k + 5, Block.stoneDoubleSlab.blockID);
			world.setBlock(i + 3, j + 0, k + 6, Block.cobblestone.blockID);
			world.setBlock(i + 3, j + 0, k + 7, Block.cobblestone.blockID);
			world.setBlock(i + 3, j + 0, k + 8, Block.planks.blockID);
			world.setBlock(i + 3, j + 0, k + 9, Block.cobblestone.blockID);
			world.setBlock(i + 3, j + 0, k + 10, Block.cobblestone.blockID);
			world.setBlock(i + 3, j + 1, k + 0, Block.cobblestone.blockID);
			world.setBlock(i + 3, j + 1, k + 1, Block.chest.blockID);
			world.setBlock(i + 3, j + 1, k + 2, 0);
			world.setBlock(i + 3, j + 1, k + 3, 0);
			world.setBlock(i + 3, j + 1, k + 4, 0);
			world.setBlock(i + 3, j + 1, k + 5, Block.furnaceIdle.blockID);
			world.setBlock(i + 3, j + 1, k + 6, Block.workbench.blockID);
			world.setBlock(i + 3, j + 1, k + 7, Block.cobblestone.blockID);
			world.setBlock(i + 3, j + 1, k + 8, 0);
			world.setBlock(i + 3, j + 1, k + 9, Block.cobblestone.blockID);
			world.setBlock(i + 3, j + 1, k + 10, Block.cobblestone.blockID);
			world.setBlock(i + 3, j + 2, k + 0, Block.cobblestone.blockID);
			world.setBlock(i + 3, j + 2, k + 1, Block.chest.blockID);
			world.setBlock(i + 3, j + 2, k + 2, 0);
			world.setBlock(i + 3, j + 2, k + 3, 0);
			world.setBlock(i + 3, j + 2, k + 4, 0);
			world.setBlock(i + 3, j + 2, k + 5, 0);
			world.setBlock(i + 3, j + 2, k + 6, Block.cobblestone.blockID);
			world.setBlock(i + 3, j + 2, k + 7, Block.cobblestone.blockID);
			world.setBlock(i + 3, j + 2, k + 8, 0);
			world.setBlock(i + 3, j + 2, k + 9, Block.cobblestone.blockID);
			world.setBlock(i + 3, j + 2, k + 10, Block.cobblestone.blockID);
			world.setBlock(i + 3, j + 3, k + 0, Block.cobblestone.blockID);
			world.setBlock(i + 3, j + 3, k + 1, Block.chest.blockID);
			world.setBlock(i + 3, j + 3, k + 2, 0);
			world.setBlock(i + 3, j + 3, k + 3, 0);
			world.setBlock(i + 3, j + 3, k + 4, 0);
			world.setBlock(i + 3, j + 3, k + 5, 0);
			world.setBlock(i + 3, j + 3, k + 6, Block.cobblestone.blockID);
			world.setBlock(i + 3, j + 3, k + 7, Block.cobblestone.blockID);
			world.setBlock(i + 3, j + 3, k + 8, 0);
			world.setBlock(i + 3, j + 3, k + 9, Block.cobblestone.blockID);
			world.setBlock(i + 3, j + 3, k + 10, Block.cobblestone.blockID);
			world.setBlock(i + 3, j + 4, k + 0, Block.cobblestone.blockID);
			world.setBlock(i + 3, j + 4, k + 1, Block.stoneSingleSlab.blockID);
			world.setBlock(i + 3, j + 4, k + 2, Block.planks.blockID);
			world.setBlock(i + 3, j + 4, k + 3, Block.planks.blockID);
			world.setBlock(i + 3, j + 4, k + 4, Block.planks.blockID);
			world.setBlock(i + 3, j + 4, k + 5, Block.cobblestone.blockID);
			world.setBlock(i + 3, j + 4, k + 6, Block.cobblestone.blockID);
			world.setBlock(i + 3, j + 4, k + 7, Block.cobblestone.blockID);
			world.setBlock(i + 3, j + 4, k + 8, Block.planks.blockID);
			world.setBlock(i + 3, j + 4, k + 9, Block.cobblestone.blockID);
			world.setBlock(i + 3, j + 4, k + 10, Block.cobblestone.blockID);
			world.setBlock(i + 4, j + 0, k + 0, Block.cobblestone.blockID);
			world.setBlock(i + 4, j + 0, k + 1, Block.stoneDoubleSlab.blockID);
			world.setBlock(i + 4, j + 0, k + 2, Block.planks.blockID);
			world.setBlock(i + 4, j + 0, k + 3, Block.planks.blockID);
			world.setBlock(i + 4, j + 0, k + 4, Block.planks.blockID);
			world.setBlock(i + 4, j + 0, k + 5, Block.cobblestone.blockID);
			world.setBlock(i + 4, j + 0, k + 6, Block.planks.blockID);
			world.setBlock(i + 4, j + 0, k + 7, Block.planks.blockID);
			world.setBlock(i + 4, j + 0, k + 8, Block.planks.blockID);
			world.setBlock(i + 4, j + 0, k + 9, Block.planks.blockID);
			world.setBlock(i + 4, j + 0, k + 10, Block.cobblestone.blockID);
			world.setBlock(i + 4, j + 1, k + 0, Block.cobblestone.blockID);
			world.setBlock(i + 4, j + 1, k + 1, Block.stoneDoubleSlab.blockID);
			world.setBlock(i + 4, j + 1, k + 2, 0);
			world.setBlock(i + 4, j + 1, k + 3, 0);
			world.setBlock(i + 4, j + 1, k + 4, 0);
			world.setBlock(i + 4, j + 1, k + 5, Block.cobblestone.blockID);
			world.setBlock(i + 4, j + 1, k + 6, 0);
			world.setBlock(i + 4, j + 1, k + 7, 0);
			world.setBlock(i + 4, j + 1, k + 8, 0);
			world.setBlock(i + 4, j + 1, k + 9, 0);
			world.setBlock(i + 4, j + 1, k + 10, Block.cobblestone.blockID);
			world.setBlock(i + 4, j + 2, k + 0, Block.cobblestone.blockID);
			world.setBlock(i + 4, j + 2, k + 1, Block.stoneDoubleSlab.blockID);
			world.setBlock(i + 4, j + 2, k + 2, 0);
			world.setBlock(i + 4, j + 2, k + 3, 0);
			world.setBlock(i + 4, j + 2, k + 4, 0);
			world.setBlock(i + 4, j + 2, k + 5, Block.cobblestone.blockID);
			world.setBlock(i + 4, j + 2, k + 6, 0);
			world.setBlock(i + 4, j + 2, k + 7, 0);
			world.setBlock(i + 4, j + 2, k + 8, 0);
			world.setBlock(i + 4, j + 2, k + 9, 0);
			world.setBlock(i + 4, j + 2, k + 10, Block.cobblestone.blockID);
			world.setBlock(i + 4, j + 3, k + 0, Block.cobblestone.blockID);
			world.setBlock(i + 4, j + 3, k + 1, Block.stoneDoubleSlab.blockID);
			world.setBlock(i + 4, j + 3, k + 2, 0);
			world.setBlock(i + 4, j + 3, k + 3, 0);
			world.setBlock(i + 4, j + 3, k + 4, 0);
			world.setBlock(i + 4, j + 3, k + 5, Block.cobblestone.blockID);
			world.setBlock(i + 4, j + 3, k + 6, 0);
			world.setBlock(i + 4, j + 3, k + 7, 0);
			world.setBlock(i + 4, j + 3, k + 8, 0);
			world.setBlock(i + 4, j + 3, k + 9, 0);
			world.setBlock(i + 4, j + 3, k + 10, Block.cobblestone.blockID);
			world.setBlock(i + 4, j + 4, k + 0, Block.cobblestone.blockID);
			world.setBlock(i + 4, j + 4, k + 1, Block.stoneDoubleSlab.blockID);
			world.setBlock(i + 4, j + 4, k + 2, Block.planks.blockID);
			world.setBlock(i + 4, j + 4, k + 3, Block.planks.blockID);
			world.setBlock(i + 4, j + 4, k + 4, Block.planks.blockID);
			world.setBlock(i + 4, j + 4, k + 5, Block.cobblestone.blockID);
			world.setBlock(i + 4, j + 4, k + 6, Block.glowStone.blockID);
			world.setBlock(i + 4, j + 4, k + 7, Block.planks.blockID);
			world.setBlock(i + 4, j + 4, k + 8, Block.planks.blockID);
			world.setBlock(i + 4, j + 4, k + 9, Block.planks.blockID);
			world.setBlock(i + 4, j + 4, k + 10, Block.cobblestone.blockID);
			world.setBlock(i + 5, j + 0, k + 0, Block.cobblestone.blockID);
			world.setBlock(i + 5, j + 0, k + 1, Block.cobblestone.blockID);
			world.setBlock(i + 5, j + 0, k + 2, Block.cobblestone.blockID);
			world.setBlock(i + 5, j + 0, k + 3, Block.cobblestone.blockID);
			world.setBlock(i + 5, j + 0, k + 4, Block.planks.blockID);
			world.setBlock(i + 5, j + 0, k + 5, Block.cobblestone.blockID);
			world.setBlock(i + 5, j + 0, k + 6, Block.planks.blockID);
			world.setBlock(i + 5, j + 0, k + 7, Block.planks.blockID);
			world.setBlock(i + 5, j + 0, k + 8, Block.planks.blockID);
			world.setBlock(i + 5, j + 0, k + 9, Block.planks.blockID);
			world.setBlock(i + 5, j + 0, k + 10, Block.cobblestone.blockID);
			world.setBlock(i + 5, j + 1, k + 0, Block.cobblestone.blockID);
			world.setBlock(i + 5, j + 1, k + 1, Block.cobblestone.blockID);
			world.setBlock(i + 5, j + 1, k + 2, Block.cobblestone.blockID);
			world.setBlock(i + 5, j + 1, k + 3, Block.cobblestone.blockID);
			world.setBlock(i + 5, j + 1, k + 4, 0);
			world.setBlock(i + 5, j + 1, k + 5, Block.cobblestone.blockID);
			world.setBlock(i + 5, j + 1, k + 6, 0);
			world.setBlock(i + 5, j + 1, k + 7, 0);
			world.setBlock(i + 5, j + 1, k + 8, 0);
			world.setBlock(i + 5, j + 1, k + 9, 0);
			world.setBlock(i + 5, j + 1, k + 10, Block.cobblestone.blockID);
			world.setBlock(i + 5, j + 2, k + 0, Block.cobblestone.blockID);
			world.setBlock(i + 5, j + 2, k + 1, Block.cobblestone.blockID);
			world.setBlock(i + 5, j + 2, k + 2, Block.cobblestone.blockID);
			world.setBlock(i + 5, j + 2, k + 3, Block.cobblestone.blockID);
			world.setBlock(i + 5, j + 2, k + 4, 0);
			world.setBlock(i + 5, j + 2, k + 5, Block.cobblestone.blockID);
			world.setBlock(i + 5, j + 2, k + 6, 0);
			world.setBlock(i + 5, j + 2, k + 7, 0);
			world.setBlock(i + 5, j + 2, k + 8, 0);
			world.setBlock(i + 5, j + 2, k + 9, 0);
			world.setBlock(i + 5, j + 2, k + 10, Block.cobblestone.blockID);
			world.setBlock(i + 5, j + 3, k + 0, Block.cobblestone.blockID);
			world.setBlock(i + 5, j + 3, k + 1, Block.cobblestone.blockID);
			world.setBlock(i + 5, j + 3, k + 2, Block.cobblestone.blockID);
			world.setBlock(i + 5, j + 3, k + 3, Block.cobblestone.blockID);
			world.setBlock(i + 5, j + 3, k + 4, 0);
			world.setBlock(i + 5, j + 3, k + 5, Block.cobblestone.blockID);
			world.setBlock(i + 5, j + 3, k + 6, 0);
			world.setBlock(i + 5, j + 3, k + 7, 0);
			world.setBlock(i + 5, j + 3, k + 8, 0);
			world.setBlock(i + 5, j + 3, k + 9, 0);
			world.setBlock(i + 5, j + 3, k + 10, Block.cobblestone.blockID);
			world.setBlock(i + 5, j + 4, k + 0, Block.cobblestone.blockID);
			world.setBlock(i + 5, j + 4, k + 1, Block.cobblestone.blockID);
			world.setBlock(i + 5, j + 4, k + 2, Block.cobblestone.blockID);
			world.setBlock(i + 5, j + 4, k + 3, Block.cobblestone.blockID);
			world.setBlock(i + 5, j + 4, k + 4, Block.planks.blockID);
			world.setBlock(i + 5, j + 4, k + 5, Block.cobblestone.blockID);
			world.setBlock(i + 5, j + 4, k + 6, Block.planks.blockID);
			world.setBlock(i + 5, j + 4, k + 7, Block.planks.blockID);
			world.setBlock(i + 5, j + 4, k + 8, Block.planks.blockID);
			world.setBlock(i + 5, j + 4, k + 9, Block.planks.blockID);
			world.setBlock(i + 5, j + 4, k + 10, Block.cobblestone.blockID);
			world.setBlock(i + 6, j + 0, k + 0, Block.stoneSingleSlab.blockID);
			world.setBlock(i + 6, j + 0, k + 1, Block.cobblestone.blockID);
			world.setBlock(i + 6, j + 0, k + 2, Block.cobblestone.blockID);
			world.setBlock(i + 6, j + 0, k + 3, Block.cobblestone.blockID);
			world.setBlock(i + 6, j + 0, k + 4, Block.cobblestone.blockID);
			world.setBlock(i + 6, j + 0, k + 5, Block.cobblestone.blockID);
			world.setBlock(i + 6, j + 0, k + 6, Block.planks.blockID);
			world.setBlock(i + 6, j + 0, k + 7, Block.planks.blockID);
			world.setBlock(i + 6, j + 0, k + 8, Block.planks.blockID);
			world.setBlock(i + 6, j + 0, k + 9, Block.planks.blockID);
			world.setBlock(i + 6, j + 0, k + 10, Block.cobblestone.blockID);
			world.setBlock(i + 6, j + 1, k + 0, 0);
			world.setBlock(i + 6, j + 1, k + 1, 0);
			world.setBlock(i + 6, j + 1, k + 2, 0);
			world.setBlock(i + 6, j + 1, k + 3, 0);
			world.setBlock(i + 6, j + 1, k + 4, 0);
			world.setBlock(i + 6, j + 1, k + 5, Block.cobblestone.blockID);
			world.setBlock(i + 6, j + 1, k + 6, 0);
			world.setBlock(i + 6, j + 1, k + 7, 0);
			world.setBlock(i + 6, j + 1, k + 8, 0);
			world.setBlock(i + 6, j + 1, k + 9, 0);
			world.setBlock(i + 6, j + 1, k + 10, Block.cobblestone.blockID);
			world.setBlock(i + 6, j + 2, k + 0, 0);
			world.setBlock(i + 6, j + 2, k + 1, 0);
			world.setBlock(i + 6, j + 2, k + 2, 0);
			world.setBlock(i + 6, j + 2, k + 3, 0);
			world.setBlock(i + 6, j + 2, k + 4, 0);
			world.setBlock(i + 6, j + 2, k + 5, Block.cobblestone.blockID);
			world.setBlock(i + 6, j + 2, k + 6, 0);
			world.setBlock(i + 6, j + 2, k + 7, 0);
			world.setBlock(i + 6, j + 2, k + 8, 0);
			world.setBlock(i + 6, j + 2, k + 9, 0);
			world.setBlock(i + 6, j + 2, k + 10, Block.cobblestone.blockID);
			world.setBlock(i + 6, j + 3, k + 0, 0);
			world.setBlock(i + 6, j + 3, k + 1, 0);
			world.setBlock(i + 6, j + 3, k + 2, 0);
			world.setBlock(i + 6, j + 3, k + 3, 0);
			world.setBlock(i + 6, j + 3, k + 4, 0);
			world.setBlock(i + 6, j + 3, k + 5, Block.cobblestone.blockID);
			world.setBlock(i + 6, j + 3, k + 6, 0);
			world.setBlock(i + 6, j + 3, k + 7, 0);
			world.setBlock(i + 6, j + 3, k + 8, 0);
			world.setBlock(i + 6, j + 3, k + 9, 0);
			world.setBlock(i + 6, j + 3, k + 10, Block.cobblestone.blockID);
			world.setBlock(i + 6, j + 4, k + 0, Block.planks.blockID);
			world.setBlock(i + 6, j + 4, k + 1, Block.planks.blockID);
			world.setBlock(i + 6, j + 4, k + 2, Block.planks.blockID);
			world.setBlock(i + 6, j + 4, k + 3, Block.planks.blockID);
			world.setBlock(i + 6, j + 4, k + 4, Block.planks.blockID);
			world.setBlock(i + 6, j + 4, k + 5, Block.cobblestone.blockID);
			world.setBlock(i + 6, j + 4, k + 6, Block.planks.blockID);
			world.setBlock(i + 6, j + 4, k + 7, Block.planks.blockID);
			world.setBlock(i + 6, j + 4, k + 8, Block.planks.blockID);
			world.setBlock(i + 6, j + 4, k + 9, Block.planks.blockID);
			world.setBlock(i + 6, j + 4, k + 10, Block.cobblestone.blockID);
			world.setBlock(i + 7, j + 0, k + 0, Block.stoneSingleSlab.blockID);
			world.setBlock(i + 7, j + 0, k + 1, Block.cobblestone.blockID);
			world.setBlock(i + 7, j + 0, k + 2, Block.cobblestone.blockID);
			world.setBlock(i + 7, j + 0, k + 3, Block.cobblestone.blockID);
			world.setBlock(i + 7, j + 0, k + 4, Block.cobblestone.blockID);
			world.setBlock(i + 7, j + 0, k + 5, Block.cobblestone.blockID);
			world.setBlock(i + 7, j + 0, k + 6, Block.planks.blockID);
			world.setBlock(i + 7, j + 0, k + 7, Block.planks.blockID);
			world.setBlock(i + 7, j + 0, k + 8, Block.planks.blockID);
			world.setBlock(i + 7, j + 0, k + 9, Block.planks.blockID);
			world.setBlock(i + 7, j + 0, k + 10, Block.cobblestone.blockID);
			world.setBlock(i + 7, j + 1, k + 0, 0);
			world.setBlock(i + 7, j + 1, k + 1, 0);
			world.setBlock(i + 7, j + 1, k + 2, 0);
			world.setBlock(i + 7, j + 1, k + 3, 0);
			world.setBlock(i + 7, j + 1, k + 4, 0);
			world.setBlock(i + 7, j + 1, k + 5, Block.cobblestone.blockID);
			world.setBlock(i + 7, j + 1, k + 6, 0);
			world.setBlock(i + 7, j + 1, k + 7, 0);
			world.setBlock(i + 7, j + 1, k + 8, 0);
			world.setBlock(i + 7, j + 1, k + 9, 0);
			world.setBlock(i + 7, j + 1, k + 10, Block.cobblestone.blockID);
			world.setBlock(i + 7, j + 2, k + 0, 0);
			world.setBlock(i + 7, j + 2, k + 1, 0);
			world.setBlock(i + 7, j + 2, k + 2, 0);
			world.setBlock(i + 7, j + 2, k + 3, 0);
			world.setBlock(i + 7, j + 2, k + 4, 0);
			world.setBlock(i + 7, j + 2, k + 5, Block.cobblestone.blockID);
			world.setBlock(i + 7, j + 2, k + 6, 0);
			world.setBlock(i + 7, j + 2, k + 7, 0);
			world.setBlock(i + 7, j + 2, k + 8, 0);
			world.setBlock(i + 7, j + 2, k + 9, 0);
			world.setBlock(i + 7, j + 2, k + 10, Block.cobblestone.blockID);
			world.setBlock(i + 7, j + 3, k + 0, 0);
			world.setBlock(i + 7, j + 3, k + 1, 0);
			world.setBlock(i + 7, j + 3, k + 2, 0);
			world.setBlock(i + 7, j + 3, k + 3, 0);
			world.setBlock(i + 7, j + 3, k + 4, 0);
			world.setBlock(i + 7, j + 3, k + 5, Block.cobblestone.blockID);
			world.setBlock(i + 7, j + 3, k + 6, 0);
			world.setBlock(i + 7, j + 3, k + 7, 0);
			world.setBlock(i + 7, j + 3, k + 8, 0);
			world.setBlock(i + 7, j + 3, k + 9, 0);
			world.setBlock(i + 7, j + 3, k + 10, Block.cobblestone.blockID);
			world.setBlock(i + 7, j + 4, k + 0, Block.planks.blockID);
			world.setBlock(i + 7, j + 4, k + 1, Block.planks.blockID);
			world.setBlock(i + 7, j + 4, k + 2, Block.planks.blockID);
			world.setBlock(i + 7, j + 4, k + 3, Block.planks.blockID);
			world.setBlock(i + 7, j + 4, k + 4, Block.planks.blockID);
			world.setBlock(i + 7, j + 4, k + 5, Block.cobblestone.blockID);
			world.setBlock(i + 7, j + 4, k + 6, Block.planks.blockID);
			world.setBlock(i + 7, j + 4, k + 7, Block.planks.blockID);
			world.setBlock(i + 7, j + 4, k + 8, Block.planks.blockID);
			world.setBlock(i + 7, j + 4, k + 9, Block.planks.blockID);
			world.setBlock(i + 7, j + 4, k + 10, Block.cobblestone.blockID);
			world.setBlock(i + 8, j + 0, k + 0, Block.cobblestone.blockID);
			world.setBlock(i + 8, j + 0, k + 1, Block.cobblestone.blockID);
			world.setBlock(i + 8, j + 0, k + 2, Block.cobblestone.blockID);
			world.setBlock(i + 8, j + 0, k + 3, Block.cobblestone.blockID);
			world.setBlock(i + 8, j + 0, k + 4, Block.cobblestone.blockID);
			world.setBlock(i + 8, j + 0, k + 5, Block.cobblestone.blockID);
			world.setBlock(i + 8, j + 0, k + 6, Block.cobblestone.blockID);
			world.setBlock(i + 8, j + 0, k + 7, Block.cobblestone.blockID);
			world.setBlock(i + 8, j + 0, k + 8, Block.cobblestone.blockID);
			world.setBlock(i + 8, j + 0, k + 9, Block.cobblestone.blockID);
			world.setBlock(i + 8, j + 0, k + 10, Block.cobblestone.blockID);
			world.setBlock(i + 8, j + 1, k + 0, Block.cobblestone.blockID);
			world.setBlock(i + 8, j + 1, k + 1, Block.cobblestone.blockID);
			world.setBlock(i + 8, j + 1, k + 2, Block.cobblestone.blockID);
			world.setBlock(i + 8, j + 1, k + 3, Block.cobblestone.blockID);
			world.setBlock(i + 8, j + 1, k + 4, Block.cobblestone.blockID);
			world.setBlock(i + 8, j + 1, k + 5, Block.cobblestone.blockID);
			world.setBlock(i + 8, j + 1, k + 6, Block.cobblestone.blockID);
			world.setBlock(i + 8, j + 1, k + 7, Block.cobblestone.blockID);
			world.setBlock(i + 8, j + 1, k + 8, Block.cobblestone.blockID);
			world.setBlock(i + 8, j + 1, k + 9, Block.cobblestone.blockID);
			world.setBlock(i + 8, j + 1, k + 10, Block.cobblestone.blockID);
			world.setBlock(i + 8, j + 2, k + 0, Block.cobblestone.blockID);
			world.setBlock(i + 8, j + 2, k + 1, Block.cobblestone.blockID);
			world.setBlock(i + 8, j + 2, k + 2, Block.cobblestone.blockID);
			world.setBlock(i + 8, j + 2, k + 3, Block.cobblestone.blockID);
			world.setBlock(i + 8, j + 2, k + 4, Block.cobblestone.blockID);
			world.setBlock(i + 8, j + 2, k + 5, Block.cobblestone.blockID);
			world.setBlock(i + 8, j + 2, k + 6, Block.cobblestone.blockID);
			world.setBlock(i + 8, j + 2, k + 7, Block.cobblestone.blockID);
			world.setBlock(i + 8, j + 2, k + 8, Block.cobblestone.blockID);
			world.setBlock(i + 8, j + 2, k + 9, Block.cobblestone.blockID);
			world.setBlock(i + 8, j + 2, k + 10, Block.cobblestone.blockID);
			world.setBlock(i + 8, j + 3, k + 0, Block.cobblestone.blockID);
			world.setBlock(i + 8, j + 3, k + 1, Block.cobblestone.blockID);
			world.setBlock(i + 8, j + 3, k + 2, Block.cobblestone.blockID);
			world.setBlock(i + 8, j + 3, k + 3, Block.cobblestone.blockID);
			world.setBlock(i + 8, j + 3, k + 4, Block.cobblestone.blockID);
			world.setBlock(i + 8, j + 3, k + 5, Block.cobblestone.blockID);
			world.setBlock(i + 8, j + 3, k + 6, Block.cobblestone.blockID);
			world.setBlock(i + 8, j + 3, k + 7, Block.cobblestone.blockID);
			world.setBlock(i + 8, j + 3, k + 8, Block.cobblestone.blockID);
			world.setBlock(i + 8, j + 3, k + 9, Block.cobblestone.blockID);
			world.setBlock(i + 8, j + 3, k + 10, Block.cobblestone.blockID);
			world.setBlock(i + 8, j + 4, k + 0, Block.cobblestone.blockID);
			world.setBlock(i + 8, j + 4, k + 1, Block.cobblestone.blockID);
			world.setBlock(i + 8, j + 4, k + 2, Block.cobblestone.blockID);
			world.setBlock(i + 8, j + 4, k + 3, Block.cobblestone.blockID);
			world.setBlock(i + 8, j + 4, k + 4, Block.cobblestone.blockID);
			world.setBlock(i + 8, j + 4, k + 5, Block.cobblestone.blockID);
			world.setBlock(i + 8, j + 4, k + 6, Block.cobblestone.blockID);
			world.setBlock(i + 8, j + 4, k + 7, Block.cobblestone.blockID);
			world.setBlock(i + 8, j + 4, k + 8, Block.cobblestone.blockID);
			world.setBlock(i + 8, j + 4, k + 9, Block.cobblestone.blockID);
			world.setBlock(i + 8, j + 4, k + 10, Block.cobblestone.blockID);
			
		}

		return true;
	}

	
        
}