package mods.polyblockz.common.blocks.constructions;

import java.util.Random;

import mods.polyblockz.common.PolyBlockz;
import mods.polyblockz.common.main.Block_Helper;
import net.minecraft.block.Block;
import net.minecraft.world.World;
import net.minecraft.world.gen.feature.WorldGenerator;

public class BlokkHouse_big extends WorldGenerator {
	

public boolean generate(World world, Random rand, int i, int j, int k) {
	
	
		if (world.getBlockId(i, j, k) == Block_Helper.BlokkHouse_big.blockID) {
			/*
			 * Blokk House
			 */
			
				
				world.setBlock(i + 0, j + 0, k + 0, Block.wood.blockID);
				world.setBlock(i + 0, j + 0, k + 1, Block.planks.blockID);
				world.setBlock(i + 0, j + 0, k + 2, Block.planks.blockID);
				world.setBlock(i + 0, j + 0, k + 3, Block.planks.blockID);
				world.setBlock(i + 0, j + 0, k + 4, Block.planks.blockID);
				world.setBlock(i + 0, j + 0, k + 5, Block.planks.blockID);
				world.setBlock(i + 0, j + 0, k + 6, Block.planks.blockID);
				world.setBlock(i + 0, j + 0, k + 7, Block.planks.blockID);
				world.setBlock(i + 0, j + 0, k + 8, Block.wood.blockID);
				world.setBlock(i + 0, j + 1, k + 0, Block.wood.blockID);
				world.setBlock(i + 0, j + 1, k + 1, Block.planks.blockID);
				world.setBlock(i + 0, j + 1, k + 2, Block.planks.blockID);
				world.setBlock(i + 0, j + 1, k + 3, Block.planks.blockID);
				world.setBlock(i + 0, j + 1, k + 4, Block.planks.blockID);
				world.setBlock(i + 0, j + 1, k + 5, Block.planks.blockID);
				world.setBlock(i + 0, j + 1, k + 6, Block.planks.blockID);
				world.setBlock(i + 0, j + 1, k + 7, Block.planks.blockID);
				world.setBlock(i + 0, j + 1, k + 8, Block.wood.blockID);
				world.setBlock(i + 0, j + 2, k + 0, Block.wood.blockID);
				world.setBlock(i + 0, j + 2, k + 1, Block.planks.blockID);
				world.setBlock(i + 0, j + 2, k + 2, Block.glass.blockID);
				world.setBlock(i + 0, j + 2, k + 3, Block.glass.blockID);
				world.setBlock(i + 0, j + 2, k + 4, Block.planks.blockID);
				world.setBlock(i + 0, j + 2, k + 5, Block.glass.blockID);
				world.setBlock(i + 0, j + 2, k + 6, Block.glass.blockID);
				world.setBlock(i + 0, j + 2, k + 7, Block.planks.blockID);
				world.setBlock(i + 0, j + 2, k + 8, Block.wood.blockID);
				world.setBlock(i + 0, j + 3, k + 0, Block.wood.blockID);
				world.setBlock(i + 0, j + 3, k + 1, Block.planks.blockID);
				world.setBlock(i + 0, j + 3, k + 2, Block.planks.blockID);
				world.setBlock(i + 0, j + 3, k + 3, Block.planks.blockID);
				world.setBlock(i + 0, j + 3, k + 4, Block.planks.blockID);
				world.setBlock(i + 0, j + 3, k + 5, Block.planks.blockID);
				world.setBlock(i + 0, j + 3, k + 6, Block.planks.blockID);
				world.setBlock(i + 0, j + 3, k + 7, Block.planks.blockID);
				world.setBlock(i + 0, j + 3, k + 8, Block.wood.blockID);
				world.setBlock(i + 0, j + 4, k + 0, Block.wood.blockID);
				world.setBlock(i + 0, j + 4, k + 1, Block.stoneSingleSlab.blockID);
				world.setBlock(i + 0, j + 4, k + 2, Block.cobblestone.blockID);
				world.setBlock(i + 0, j + 4, k + 3, Block.cobblestone.blockID);
				world.setBlock(i + 0, j + 4, k + 4, Block.cobblestone.blockID);
				world.setBlock(i + 0, j + 4, k + 5, Block.cobblestone.blockID);
				world.setBlock(i + 0, j + 4, k + 6, Block.cobblestone.blockID);
				world.setBlock(i + 0, j + 4, k + 7, Block.cobblestone.blockID);
				world.setBlock(i + 0, j + 4, k + 8, Block.wood.blockID);
				world.setBlock(i + 0, j + 5, k + 0, 0);
				world.setBlock(i + 0, j + 5, k + 1, 0);
				world.setBlock(i + 0, j + 5, k + 2, 0);
				world.setBlock(i + 0, j + 5, k + 3, 0);
				world.setBlock(i + 0, j + 5, k + 4, 0);
				world.setBlock(i + 0, j + 5, k + 5, 0);
				world.setBlock(i + 0, j + 5, k + 6, 0);
				world.setBlock(i + 0, j + 5, k + 7, 0);
				world.setBlock(i + 0, j + 5, k + 8, 0);
				world.setBlock(i + 0, j + 6, k + 0, 0);
				world.setBlock(i + 0, j + 6, k + 1, 0);
				world.setBlock(i + 0, j + 6, k + 2, 0);
				world.setBlock(i + 0, j + 6, k + 3, 0);
				world.setBlock(i + 0, j + 6, k + 4, 0);
				world.setBlock(i + 0, j + 6, k + 5, 0);
				world.setBlock(i + 0, j + 6, k + 6, 0);
				world.setBlock(i + 0, j + 6, k + 7, 0);
				world.setBlock(i + 0, j + 6, k + 8, 0);
				world.setBlock(i + 1, j + 0, k + 0, Block.planks.blockID);
				world.setBlock(i + 1, j + 0, k + 1, Block.planks.blockID);
				world.setBlock(i + 1, j + 0, k + 2, Block.planks.blockID);
				world.setBlock(i + 1, j + 0, k + 3, Block.planks.blockID);
				world.setBlock(i + 1, j + 0, k + 4, Block.planks.blockID);
				world.setBlock(i + 1, j + 0, k + 5, Block.planks.blockID);
				world.setBlock(i + 1, j + 0, k + 6, Block.planks.blockID);
				world.setBlock(i + 1, j + 0, k + 7, Block.planks.blockID);
				world.setBlock(i + 1, j + 0, k + 8, Block.planks.blockID);
				world.setBlock(i + 1, j + 1, k + 0, Block.planks.blockID);
				world.setBlock(i + 1, j + 1, k + 1, 0);
				world.setBlock(i + 1, j + 1, k + 2, 0);
				world.setBlock(i + 1, j + 1, k + 3, 0);
				world.setBlock(i + 1, j + 1, k + 4, 0);
				world.setBlock(i + 1, j + 1, k + 5, 0);
				world.setBlock(i + 1, j + 1, k + 6, 0);
				world.setBlock(i + 1, j + 1, k + 7, Block.chest.blockID);
				world.setBlock(i + 1, j + 1, k + 8, Block.planks.blockID);
				world.setBlock(i + 1, j + 2, k + 0, Block.planks.blockID);
				world.setBlock(i + 1, j + 2, k + 1, 0);
				world.setBlock(i + 1, j + 2, k + 2, 0);
				world.setBlock(i + 1, j + 2, k + 3, 0);
				world.setBlock(i + 1, j + 2, k + 4, 0);
				world.setBlock(i + 1, j + 2, k + 5, 0);
				world.setBlock(i + 1, j + 2, k + 6, 0);
				world.setBlock(i + 1, j + 2, k + 7, 0);
				world.setBlock(i + 1, j + 2, k + 8, Block.planks.blockID);
				world.setBlock(i + 1, j + 3, k + 0, Block.planks.blockID);
				world.setBlock(i + 1, j + 3, k + 1, 0);
				world.setBlock(i + 1, j + 3, k + 2, 0);
				world.setBlock(i + 1, j + 3, k + 3, 0);
				world.setBlock(i + 1, j + 3, k + 4, 0);
				world.setBlock(i + 1, j + 3, k + 5, 0);
				world.setBlock(i + 1, j + 3, k + 6, 0);
				world.setBlock(i + 1, j + 3, k + 7, 0);
				world.setBlock(i + 1, j + 3, k + 8, Block.planks.blockID);
				world.setBlock(i + 1, j + 4, k + 0, Block.cobblestone.blockID);
				world.setBlock(i + 1, j + 4, k + 1, Block.planks.blockID);
				world.setBlock(i + 1, j + 4, k + 2, Block.planks.blockID);
				world.setBlock(i + 1, j + 4, k + 3, Block.planks.blockID);
				world.setBlock(i + 1, j + 4, k + 4, Block.planks.blockID);
				world.setBlock(i + 1, j + 4, k + 5, Block.planks.blockID);
				world.setBlock(i + 1, j + 4, k + 6, Block.planks.blockID);
				world.setBlock(i + 1, j + 4, k + 7, Block.planks.blockID);
				world.setBlock(i + 1, j + 4, k + 8, Block.cobblestone.blockID);
				world.setBlock(i + 1, j + 5, k + 0, 0);
				world.setBlock(i + 1, j + 5, k + 1, 0);
				world.setBlock(i + 1, j + 5, k + 2, 0);
				world.setBlock(i + 1, j + 5, k + 3, 0);
				world.setBlock(i + 1, j + 5, k + 4, 0);
				world.setBlock(i + 1, j + 5, k + 5, 0);
				world.setBlock(i + 1, j + 5, k + 6, 0);
				world.setBlock(i + 1, j + 5, k + 7, 0);
				world.setBlock(i + 1, j + 5, k + 8, 0);
				world.setBlock(i + 1, j + 6, k + 0, 0);
				world.setBlock(i + 1, j + 6, k + 1, 0);
				world.setBlock(i + 1, j + 6, k + 2, 0);
				world.setBlock(i + 1, j + 6, k + 3, 0);
				world.setBlock(i + 1, j + 6, k + 4, 0);
				world.setBlock(i + 1, j + 6, k + 5, 0);
				world.setBlock(i + 1, j + 6, k + 6, 0);
				world.setBlock(i + 1, j + 6, k + 7, 0);
				world.setBlock(i + 1, j + 6, k + 8, 0);
				world.setBlock(i + 2, j + 0, k + 0, Block.planks.blockID);
				world.setBlock(i + 2, j + 0, k + 1, Block.planks.blockID);
				world.setBlock(i + 2, j + 0, k + 2, Block.planks.blockID);
				world.setBlock(i + 2, j + 0, k + 3, Block.planks.blockID);
				world.setBlock(i + 2, j + 0, k + 4, Block.planks.blockID);
				world.setBlock(i + 2, j + 0, k + 5, Block.planks.blockID);
				world.setBlock(i + 2, j + 0, k + 6, Block.planks.blockID);
				world.setBlock(i + 2, j + 0, k + 7, Block.planks.blockID);
				world.setBlock(i + 2, j + 0, k + 8, Block.planks.blockID);
				world.setBlock(i + 2, j + 1, k + 0, Block.planks.blockID);
				world.setBlock(i + 2, j + 1, k + 1, 0);
				world.setBlock(i + 2, j + 1, k + 2, 0);
				world.setBlock(i + 2, j + 1, k + 3, 0);
				world.setBlock(i + 2, j + 1, k + 4, 0);
				world.setBlock(i + 2, j + 1, k + 5, 0);
				world.setBlock(i + 2, j + 1, k + 6, 0);
				world.setBlock(i + 2, j + 1, k + 7, Block.chest.blockID);
				world.setBlock(i + 2, j + 1, k + 8, Block.planks.blockID);
				world.setBlock(i + 2, j + 2, k + 0, Block.glass.blockID);
				world.setBlock(i + 2, j + 2, k + 1, 0);
				world.setBlock(i + 2, j + 2, k + 2, 0);
				world.setBlock(i + 2, j + 2, k + 3, 0);
				world.setBlock(i + 2, j + 2, k + 4, 0);
				world.setBlock(i + 2, j + 2, k + 5, 0);
				world.setBlock(i + 2, j + 2, k + 6, 0);
				world.setBlock(i + 2, j + 2, k + 7, 0);
				world.setBlock(i + 2, j + 2, k + 8, Block.glass.blockID);
				world.setBlock(i + 2, j + 3, k + 0, Block.planks.blockID);
				world.setBlock(i + 2, j + 3, k + 1, 0);
				world.setBlock(i + 2, j + 3, k + 2, 0);
				world.setBlock(i + 2, j + 3, k + 3, 0);
				world.setBlock(i + 2, j + 3, k + 4, 0);
				world.setBlock(i + 2, j + 3, k + 5, 0);
				world.setBlock(i + 2, j + 3, k + 6, 0);
				world.setBlock(i + 2, j + 3, k + 7, 0);
				world.setBlock(i + 2, j + 3, k + 8, Block.planks.blockID);
				world.setBlock(i + 2, j + 4, k + 0, Block.cobblestone.blockID);
				world.setBlock(i + 2, j + 4, k + 1, Block.planks.blockID);
				world.setBlock(i + 2, j + 4, k + 2, 0);
				world.setBlock(i + 2, j + 4, k + 3, 0);
				world.setBlock(i + 2, j + 4, k + 4, 0);
				world.setBlock(i + 2, j + 4, k + 5, 0);
				world.setBlock(i + 2, j + 4, k + 6, 0);
				world.setBlock(i + 2, j + 4, k + 7, Block.planks.blockID);
				world.setBlock(i + 2, j + 4, k + 8, Block.cobblestone.blockID);
				world.setBlock(i + 2, j + 5, k + 0, 0);
				world.setBlock(i + 2, j + 5, k + 1, 0);
				world.setBlock(i + 2, j + 5, k + 2, Block.cobblestone.blockID);
				world.setBlock(i + 2, j + 5, k + 3, Block.cobblestone.blockID);
				world.setBlock(i + 2, j + 5, k + 4, Block.cobblestone.blockID);
				world.setBlock(i + 2, j + 5, k + 5, Block.cobblestone.blockID);
				world.setBlock(i + 2, j + 5, k + 6, Block.cobblestone.blockID);
				world.setBlock(i + 2, j + 5, k + 7, 0);
				world.setBlock(i + 2, j + 5, k + 8, 0);
				world.setBlock(i + 2, j + 6, k + 0, 0);
				world.setBlock(i + 2, j + 6, k + 1, 0);
				world.setBlock(i + 2, j + 6, k + 2, 0);
				world.setBlock(i + 2, j + 6, k + 3, 0);
				world.setBlock(i + 2, j + 6, k + 4, 0);
				world.setBlock(i + 2, j + 6, k + 5, 0);
				world.setBlock(i + 2, j + 6, k + 6, 0);
				world.setBlock(i + 2, j + 6, k + 7, 0);
				world.setBlock(i + 2, j + 6, k + 8, 0);
				world.setBlock(i + 3, j + 0, k + 0, Block.planks.blockID);
				world.setBlock(i + 3, j + 0, k + 1, Block.planks.blockID);
				world.setBlock(i + 3, j + 0, k + 2, Block.planks.blockID);
				world.setBlock(i + 3, j + 0, k + 3, Block.planks.blockID);
				world.setBlock(i + 3, j + 0, k + 4, Block.planks.blockID);
				world.setBlock(i + 3, j + 0, k + 5, Block.planks.blockID);
				world.setBlock(i + 3, j + 0, k + 6, Block.planks.blockID);
				world.setBlock(i + 3, j + 0, k + 7, Block.planks.blockID);
				world.setBlock(i + 3, j + 0, k + 8, Block.planks.blockID);
				world.setBlock(i + 3, j + 1, k + 0, Block.planks.blockID);
				world.setBlock(i + 3, j + 1, k + 1, 0);
				world.setBlock(i + 3, j + 1, k + 2, 0);
				world.setBlock(i + 3, j + 1, k + 3, 0);
				world.setBlock(i + 3, j + 1, k + 4, 0);
				world.setBlock(i + 3, j + 1, k + 5, 0);
				world.setBlock(i + 3, j + 1, k + 6, 0);
				world.setBlock(i + 3, j + 1, k + 7, 0);
				world.setBlock(i + 3, j + 1, k + 8, Block.planks.blockID);
				world.setBlock(i + 3, j + 2, k + 0, Block.planks.blockID);
				world.setBlock(i + 3, j + 2, k + 1, 0);
				world.setBlock(i + 3, j + 2, k + 2, 0);
				world.setBlock(i + 3, j + 2, k + 3, 0);
				world.setBlock(i + 3, j + 2, k + 4, 0);
				world.setBlock(i + 3, j + 2, k + 5, 0);
				world.setBlock(i + 3, j + 2, k + 6, 0);
				world.setBlock(i + 3, j + 2, k + 7, 0);
				world.setBlock(i + 3, j + 2, k + 8, Block.glass.blockID);
				world.setBlock(i + 3, j + 3, k + 0, Block.planks.blockID);
				world.setBlock(i + 3, j + 3, k + 1, 0);
				world.setBlock(i + 3, j + 3, k + 2, 0);
				world.setBlock(i + 3, j + 3, k + 3, 0);
				world.setBlock(i + 3, j + 3, k + 4, 0);
				world.setBlock(i + 3, j + 3, k + 5, 0);
				world.setBlock(i + 3, j + 3, k + 6, 0);
				world.setBlock(i + 3, j + 3, k + 7, 0);
				world.setBlock(i + 3, j + 3, k + 8, Block.planks.blockID);
				world.setBlock(i + 3, j + 4, k + 0, Block.cobblestone.blockID);
				world.setBlock(i + 3, j + 4, k + 1, Block.planks.blockID);
				world.setBlock(i + 3, j + 4, k + 2, 0);
				world.setBlock(i + 3, j + 4, k + 3, 0);
				world.setBlock(i + 3, j + 4, k + 4, 0);
				world.setBlock(i + 3, j + 4, k + 5, 0);
				world.setBlock(i + 3, j + 4, k + 6, 0);
				world.setBlock(i + 3, j + 4, k + 7, Block.planks.blockID);
				world.setBlock(i + 3, j + 4, k + 8, Block.cobblestone.blockID);
				world.setBlock(i + 3, j + 5, k + 0, 0);
				world.setBlock(i + 3, j + 5, k + 1, 0);
				world.setBlock(i + 3, j + 5, k + 2, Block.cobblestone.blockID);
				world.setBlock(i + 3, j + 5, k + 3, Block.planks.blockID);
				world.setBlock(i + 3, j + 5, k + 4, Block.planks.blockID);
				world.setBlock(i + 3, j + 5, k + 5, Block.planks.blockID);
				world.setBlock(i + 3, j + 5, k + 6, Block.cobblestone.blockID);
				world.setBlock(i + 3, j + 5, k + 7, 0);
				world.setBlock(i + 3, j + 5, k + 8, 0);
				world.setBlock(i + 3, j + 6, k + 0, 0);
				world.setBlock(i + 3, j + 6, k + 1, 0);
				world.setBlock(i + 3, j + 6, k + 2, 0);
				world.setBlock(i + 3, j + 6, k + 3, 0);
				world.setBlock(i + 3, j + 6, k + 4, 0);
				world.setBlock(i + 3, j + 6, k + 5, 0);
				world.setBlock(i + 3, j + 6, k + 6, 0);
				world.setBlock(i + 3, j + 6, k + 7, 0);
				world.setBlock(i + 3, j + 6, k + 8, 0);
				world.setBlock(i + 4, j + 0, k + 0, Block.planks.blockID);
				world.setBlock(i + 4, j + 0, k + 1, Block.planks.blockID);
				world.setBlock(i + 4, j + 0, k + 2, Block.planks.blockID);
				world.setBlock(i + 4, j + 0, k + 3, Block.planks.blockID);
				world.setBlock(i + 4, j + 0, k + 4, Block.planks.blockID);
				world.setBlock(i + 4, j + 0, k + 5, Block.planks.blockID);
				world.setBlock(i + 4, j + 0, k + 6, Block.planks.blockID);
				world.setBlock(i + 4, j + 0, k + 7, Block.planks.blockID);
				world.setBlock(i + 4, j + 0, k + 8, Block.planks.blockID);
				world.setBlock(i + 4, j + 1, k + 0, 0);
				world.setBlock(i + 4, j + 1, k + 1, 0);
				world.setBlock(i + 4, j + 1, k + 2, 0);
				world.setBlock(i + 4, j + 1, k + 3, 0);
				world.setBlock(i + 4, j + 1, k + 4, 0);
				world.setBlock(i + 4, j + 1, k + 5, 0);
				world.setBlock(i + 4, j + 1, k + 6, 0);
				world.setBlock(i + 4, j + 1, k + 7, Block.workbench.blockID);
				world.setBlock(i + 4, j + 1, k + 8, Block.planks.blockID);
				world.setBlock(i + 4, j + 2, k + 0, 0);
				world.setBlock(i + 4, j + 2, k + 1, 0);
				world.setBlock(i + 4, j + 2, k + 2, 0);
				world.setBlock(i + 4, j + 2, k + 3, 0);
				world.setBlock(i + 4, j + 2, k + 4, 0);
				world.setBlock(i + 4, j + 2, k + 5, 0);
				world.setBlock(i + 4, j + 2, k + 6, 0);
				world.setBlock(i + 4, j + 2, k + 7, 0);
				world.setBlock(i + 4, j + 2, k + 8, Block.planks.blockID);
				world.setBlock(i + 4, j + 3, k + 0, Block.planks.blockID);
				world.setBlock(i + 4, j + 3, k + 1, 0);
				world.setBlock(i + 4, j + 3, k + 2, 0);
				world.setBlock(i + 4, j + 3, k + 3, 0);
				world.setBlock(i + 4, j + 3, k + 4, 0);
				world.setBlock(i + 4, j + 3, k + 5, 0);
				world.setBlock(i + 4, j + 3, k + 6, 0);
				world.setBlock(i + 4, j + 3, k + 7, 0);
				world.setBlock(i + 4, j + 3, k + 8, Block.planks.blockID);
				world.setBlock(i + 4, j + 4, k + 0, Block.cobblestone.blockID);
				world.setBlock(i + 4, j + 4, k + 1, Block.planks.blockID);
				world.setBlock(i + 4, j + 4, k + 2, 0);
				world.setBlock(i + 4, j + 4, k + 3, 0);
				world.setBlock(i + 4, j + 4, k + 4, 0);
				world.setBlock(i + 4, j + 4, k + 5, 0);
				world.setBlock(i + 4, j + 4, k + 6, 0);
				world.setBlock(i + 4, j + 4, k + 7, Block.planks.blockID);
				world.setBlock(i + 4, j + 4, k + 8, Block.cobblestone.blockID);
				world.setBlock(i + 4, j + 5, k + 0, 0);
				world.setBlock(i + 4, j + 5, k + 1, 0);
				world.setBlock(i + 4, j + 5, k + 2, Block.cobblestone.blockID);
				world.setBlock(i + 4, j + 5, k + 3, Block.planks.blockID);
				world.setBlock(i + 4, j + 5, k + 4, 0);
				world.setBlock(i + 4, j + 5, k + 5, Block.planks.blockID);
				world.setBlock(i + 4, j + 5, k + 6, Block.cobblestone.blockID);
				world.setBlock(i + 4, j + 5, k + 7, 0);
				world.setBlock(i + 4, j + 5, k + 8, 0);
				world.setBlock(i + 4, j + 6, k + 0, 0);
				world.setBlock(i + 4, j + 6, k + 1, 0);
				world.setBlock(i + 4, j + 6, k + 2, 0);
				world.setBlock(i + 4, j + 6, k + 3, 0);
				world.setBlock(i + 4, j + 6, k + 4, Block.cobblestone.blockID);
				world.setBlock(i + 4, j + 6, k + 5, 0);
				world.setBlock(i + 4, j + 6, k + 6, 0);
				world.setBlock(i + 4, j + 6, k + 7, 0);
				world.setBlock(i + 4, j + 6, k + 8, 0);
				world.setBlock(i + 5, j + 0, k + 0, Block.planks.blockID);
				world.setBlock(i + 5, j + 0, k + 1, Block.planks.blockID);
				world.setBlock(i + 5, j + 0, k + 2, Block.planks.blockID);
				world.setBlock(i + 5, j + 0, k + 3, Block.planks.blockID);
				world.setBlock(i + 5, j + 0, k + 4, Block.planks.blockID);
				world.setBlock(i + 5, j + 0, k + 5, Block.planks.blockID);
				world.setBlock(i + 5, j + 0, k + 6, Block.planks.blockID);
				world.setBlock(i + 5, j + 0, k + 7, Block.planks.blockID);
				world.setBlock(i + 5, j + 0, k + 8, Block.planks.blockID);
				world.setBlock(i + 5, j + 1, k + 0, Block.planks.blockID);
				world.setBlock(i + 5, j + 1, k + 1, 0);
				world.setBlock(i + 5, j + 1, k + 2, 0);
				world.setBlock(i + 5, j + 1, k + 3, 0);
				world.setBlock(i + 5, j + 1, k + 4, 0);
				world.setBlock(i + 5, j + 1, k + 5, 0);
				world.setBlock(i + 5, j + 1, k + 6, 0);
				world.setBlock(i + 5, j + 1, k + 7, 0);
				world.setBlock(i + 5, j + 1, k + 8, Block.planks.blockID);
				world.setBlock(i + 5, j + 2, k + 0, Block.planks.blockID);
				world.setBlock(i + 5, j + 2, k + 1, 0);
				world.setBlock(i + 5, j + 2, k + 2, 0);
				world.setBlock(i + 5, j + 2, k + 3, 0);
				world.setBlock(i + 5, j + 2, k + 4, 0);
				world.setBlock(i + 5, j + 2, k + 5, 0);
				world.setBlock(i + 5, j + 2, k + 6, 0);
				world.setBlock(i + 5, j + 2, k + 7, 0);
				world.setBlock(i + 5, j + 2, k + 8, Block.glass.blockID);
				world.setBlock(i + 5, j + 3, k + 0, Block.planks.blockID);
				world.setBlock(i + 5, j + 3, k + 1, 0);
				world.setBlock(i + 5, j + 3, k + 2, 0);
				world.setBlock(i + 5, j + 3, k + 3, 0);
				world.setBlock(i + 5, j + 3, k + 4, 0);
				world.setBlock(i + 5, j + 3, k + 5, 0);
				world.setBlock(i + 5, j + 3, k + 6, 0);
				world.setBlock(i + 5, j + 3, k + 7, 0);
				world.setBlock(i + 5, j + 3, k + 8, Block.planks.blockID);
				world.setBlock(i + 5, j + 4, k + 0, Block.cobblestone.blockID);
				world.setBlock(i + 5, j + 4, k + 1, Block.planks.blockID);
				world.setBlock(i + 5, j + 4, k + 2, 0);
				world.setBlock(i + 5, j + 4, k + 3, 0);
				world.setBlock(i + 5, j + 4, k + 4, 0);
				world.setBlock(i + 5, j + 4, k + 5, 0);
				world.setBlock(i + 5, j + 4, k + 6, 0);
				world.setBlock(i + 5, j + 4, k + 7, Block.planks.blockID);
				world.setBlock(i + 5, j + 4, k + 8, Block.cobblestone.blockID);
				world.setBlock(i + 5, j + 5, k + 0, 0);
				world.setBlock(i + 5, j + 5, k + 1, 0);
				world.setBlock(i + 5, j + 5, k + 2, Block.cobblestone.blockID);
				world.setBlock(i + 5, j + 5, k + 3, Block.planks.blockID);
				world.setBlock(i + 5, j + 5, k + 4, Block.planks.blockID);
				world.setBlock(i + 5, j + 5, k + 5, Block.planks.blockID);
				world.setBlock(i + 5, j + 5, k + 6, Block.cobblestone.blockID);
				world.setBlock(i + 5, j + 5, k + 7, 0);
				world.setBlock(i + 5, j + 5, k + 8, 0);
				world.setBlock(i + 5, j + 6, k + 0, 0);
				world.setBlock(i + 5, j + 6, k + 1, 0);
				world.setBlock(i + 5, j + 6, k + 2, 0);
				world.setBlock(i + 5, j + 6, k + 3, 0);
				world.setBlock(i + 5, j + 6, k + 4, 0);
				world.setBlock(i + 5, j + 6, k + 5, 0);
				world.setBlock(i + 5, j + 6, k + 6, 0);
				world.setBlock(i + 5, j + 6, k + 7, 0);
				world.setBlock(i + 5, j + 6, k + 8, 0);
				world.setBlock(i + 6, j + 0, k + 0, Block.planks.blockID);
				world.setBlock(i + 6, j + 0, k + 1, Block.planks.blockID);
				world.setBlock(i + 6, j + 0, k + 2, Block.planks.blockID);
				world.setBlock(i + 6, j + 0, k + 3, Block.planks.blockID);
				world.setBlock(i + 6, j + 0, k + 4, Block.planks.blockID);
				world.setBlock(i + 6, j + 0, k + 5, Block.planks.blockID);
				world.setBlock(i + 6, j + 0, k + 6, Block.planks.blockID);
				world.setBlock(i + 6, j + 0, k + 7, Block.planks.blockID);
				world.setBlock(i + 6, j + 0, k + 8, Block.planks.blockID);
				world.setBlock(i + 6, j + 1, k + 0, Block.planks.blockID);
				world.setBlock(i + 6, j + 1, k + 1, 0);
				world.setBlock(i + 6, j + 1, k + 2, 0);
				world.setBlock(i + 6, j + 1, k + 3, 0);
				world.setBlock(i + 6, j + 1, k + 4, 0);
				world.setBlock(i + 6, j + 1, k + 5, 0);
				world.setBlock(i + 6, j + 1, k + 6, 0);
				world.setBlock(i + 6, j + 1, k + 7, Block.furnaceIdle.blockID);
				world.setBlock(i + 6, j + 1, k + 8, Block.planks.blockID);
				world.setBlock(i + 6, j + 2, k + 0, Block.glass.blockID);
				world.setBlock(i + 6, j + 2, k + 1, 0);
				world.setBlock(i + 6, j + 2, k + 2, 0);
				world.setBlock(i + 6, j + 2, k + 3, 0);
				world.setBlock(i + 6, j + 2, k + 4, 0);
				world.setBlock(i + 6, j + 2, k + 5, 0);
				world.setBlock(i + 6, j + 2, k + 6, 0);
				world.setBlock(i + 6, j + 2, k + 7, 0);
				world.setBlock(i + 6, j + 2, k + 8, Block.glass.blockID);
				world.setBlock(i + 6, j + 3, k + 0, Block.planks.blockID);
				world.setBlock(i + 6, j + 3, k + 1, 0);
				world.setBlock(i + 6, j + 3, k + 2, 0);
				world.setBlock(i + 6, j + 3, k + 3, 0);
				world.setBlock(i + 6, j + 3, k + 4, 0);
				world.setBlock(i + 6, j + 3, k + 5, 0);
				world.setBlock(i + 6, j + 3, k + 6, 0);
				world.setBlock(i + 6, j + 3, k + 7, 0);
				world.setBlock(i + 6, j + 3, k + 8, Block.planks.blockID);
				world.setBlock(i + 6, j + 4, k + 0, Block.cobblestone.blockID);
				world.setBlock(i + 6, j + 4, k + 1, Block.planks.blockID);
				world.setBlock(i + 6, j + 4, k + 2, 0);
				world.setBlock(i + 6, j + 4, k + 3, 0);
				world.setBlock(i + 6, j + 4, k + 4, 0);
				world.setBlock(i + 6, j + 4, k + 5, 0);
				world.setBlock(i + 6, j + 4, k + 6, 0);
				world.setBlock(i + 6, j + 4, k + 7, Block.planks.blockID);
				world.setBlock(i + 6, j + 4, k + 8, Block.cobblestone.blockID);
				world.setBlock(i + 6, j + 5, k + 0, 0);
				world.setBlock(i + 6, j + 5, k + 1, 0);
				world.setBlock(i + 6, j + 5, k + 2, Block.cobblestone.blockID);
				world.setBlock(i + 6, j + 5, k + 3, Block.cobblestone.blockID);
				world.setBlock(i + 6, j + 5, k + 4, Block.cobblestone.blockID);
				world.setBlock(i + 6, j + 5, k + 5, Block.cobblestone.blockID);
				world.setBlock(i + 6, j + 5, k + 6, Block.cobblestone.blockID);
				world.setBlock(i + 6, j + 5, k + 7, 0);
				world.setBlock(i + 6, j + 5, k + 8, 0);
				world.setBlock(i + 6, j + 6, k + 0, 0);
				world.setBlock(i + 6, j + 6, k + 1, 0);
				world.setBlock(i + 6, j + 6, k + 2, 0);
				world.setBlock(i + 6, j + 6, k + 3, 0);
				world.setBlock(i + 6, j + 6, k + 4, 0);
				world.setBlock(i + 6, j + 6, k + 5, 0);
				world.setBlock(i + 6, j + 6, k + 6, 0);
				world.setBlock(i + 6, j + 6, k + 7, 0);
				world.setBlock(i + 6, j + 6, k + 8, 0);
				world.setBlock(i + 7, j + 0, k + 0, Block.planks.blockID);
				world.setBlock(i + 7, j + 0, k + 1, Block.planks.blockID);
				world.setBlock(i + 7, j + 0, k + 2, Block.planks.blockID);
				world.setBlock(i + 7, j + 0, k + 3, Block.planks.blockID);
				world.setBlock(i + 7, j + 0, k + 4, Block.planks.blockID);
				world.setBlock(i + 7, j + 0, k + 5, Block.planks.blockID);
				world.setBlock(i + 7, j + 0, k + 6, Block.planks.blockID);
				world.setBlock(i + 7, j + 0, k + 7, Block.planks.blockID);
				world.setBlock(i + 7, j + 0, k + 8, Block.planks.blockID);
				world.setBlock(i + 7, j + 1, k + 0, Block.planks.blockID);
				world.setBlock(i + 7, j + 1, k + 1, 0);
				world.setBlock(i + 7, j + 1, k + 2, 0);
				world.setBlock(i + 7, j + 1, k + 3, 0);
				world.setBlock(i + 7, j + 1, k + 4, 0);
				world.setBlock(i + 7, j + 1, k + 5, 0);
				world.setBlock(i + 7, j + 1, k + 6, 0);
				world.setBlock(i + 7, j + 1, k + 7, Block.furnaceIdle.blockID);
				world.setBlock(i + 7, j + 1, k + 8, Block.planks.blockID);
				world.setBlock(i + 7, j + 2, k + 0, Block.planks.blockID);
				world.setBlock(i + 7, j + 2, k + 1, 0);
				world.setBlock(i + 7, j + 2, k + 2, 0);
				world.setBlock(i + 7, j + 2, k + 3, 0);
				world.setBlock(i + 7, j + 2, k + 4, 0);
				world.setBlock(i + 7, j + 2, k + 5, 0);
				world.setBlock(i + 7, j + 2, k + 6, 0);
				world.setBlock(i + 7, j + 2, k + 7, 0);
				world.setBlock(i + 7, j + 2, k + 8, Block.planks.blockID);
				world.setBlock(i + 7, j + 3, k + 0, Block.planks.blockID);
				world.setBlock(i + 7, j + 3, k + 1, 0);
				world.setBlock(i + 7, j + 3, k + 2, 0);
				world.setBlock(i + 7, j + 3, k + 3, 0);
				world.setBlock(i + 7, j + 3, k + 4, 0);
				world.setBlock(i + 7, j + 3, k + 5, 0);
				world.setBlock(i + 7, j + 3, k + 6, 0);
				world.setBlock(i + 7, j + 3, k + 7, 0);
				world.setBlock(i + 7, j + 3, k + 8, Block.planks.blockID);
				world.setBlock(i + 7, j + 4, k + 0, Block.cobblestone.blockID);
				world.setBlock(i + 7, j + 4, k + 1, Block.planks.blockID);
				world.setBlock(i + 7, j + 4, k + 2, Block.planks.blockID);
				world.setBlock(i + 7, j + 4, k + 3, Block.planks.blockID);
				world.setBlock(i + 7, j + 4, k + 4, Block.planks.blockID);
				world.setBlock(i + 7, j + 4, k + 5, Block.planks.blockID);
				world.setBlock(i + 7, j + 4, k + 6, Block.planks.blockID);
				world.setBlock(i + 7, j + 4, k + 7, Block.planks.blockID);
				world.setBlock(i + 7, j + 4, k + 8, Block.cobblestone.blockID);
				world.setBlock(i + 7, j + 5, k + 0, 0);
				world.setBlock(i + 7, j + 5, k + 1, 0);
				world.setBlock(i + 7, j + 5, k + 2, 0);
				world.setBlock(i + 7, j + 5, k + 3, 0);
				world.setBlock(i + 7, j + 5, k + 4, 0);
				world.setBlock(i + 7, j + 5, k + 5, 0);
				world.setBlock(i + 7, j + 5, k + 6, 0);
				world.setBlock(i + 7, j + 5, k + 7, 0);
				world.setBlock(i + 7, j + 5, k + 8, 0);
				world.setBlock(i + 7, j + 6, k + 0, 0);
				world.setBlock(i + 7, j + 6, k + 1, 0);
				world.setBlock(i + 7, j + 6, k + 2, 0);
				world.setBlock(i + 7, j + 6, k + 3, 0);
				world.setBlock(i + 7, j + 6, k + 4, 0);
				world.setBlock(i + 7, j + 6, k + 5, 0);
				world.setBlock(i + 7, j + 6, k + 6, 0);
				world.setBlock(i + 7, j + 6, k + 7, 0);
				world.setBlock(i + 7, j + 6, k + 8, 0);
				world.setBlock(i + 8, j + 0, k + 0, Block.wood.blockID);
				world.setBlock(i + 8, j + 0, k + 1, Block.planks.blockID);
				world.setBlock(i + 8, j + 0, k + 2, Block.planks.blockID);
				world.setBlock(i + 8, j + 0, k + 3, Block.planks.blockID);
				world.setBlock(i + 8, j + 0, k + 4, Block.planks.blockID);
				world.setBlock(i + 8, j + 0, k + 5, Block.planks.blockID);
				world.setBlock(i + 8, j + 0, k + 6, Block.planks.blockID);
				world.setBlock(i + 8, j + 0, k + 7, Block.planks.blockID);
				world.setBlock(i + 8, j + 0, k + 8, Block.wood.blockID);
				world.setBlock(i + 8, j + 1, k + 0, Block.wood.blockID);
				world.setBlock(i + 8, j + 1, k + 1, Block.planks.blockID);
				world.setBlock(i + 8, j + 1, k + 2, Block.planks.blockID);
				world.setBlock(i + 8, j + 1, k + 3, Block.planks.blockID);
				world.setBlock(i + 8, j + 1, k + 4, Block.planks.blockID);
				world.setBlock(i + 8, j + 1, k + 5, Block.planks.blockID);
				world.setBlock(i + 8, j + 1, k + 6, Block.planks.blockID);
				world.setBlock(i + 8, j + 1, k + 7, Block.planks.blockID);
				world.setBlock(i + 8, j + 1, k + 8, Block.wood.blockID);
				world.setBlock(i + 8, j + 2, k + 0, Block.wood.blockID);
				world.setBlock(i + 8, j + 2, k + 1, Block.planks.blockID);
				world.setBlock(i + 8, j + 2, k + 2, Block.glass.blockID);
				world.setBlock(i + 8, j + 2, k + 3, Block.glass.blockID);
				world.setBlock(i + 8, j + 2, k + 4, Block.planks.blockID);
				world.setBlock(i + 8, j + 2, k + 5, Block.glass.blockID);
				world.setBlock(i + 8, j + 2, k + 6, Block.glass.blockID);
				world.setBlock(i + 8, j + 2, k + 7, Block.planks.blockID);
				world.setBlock(i + 8, j + 2, k + 8, Block.wood.blockID);
				world.setBlock(i + 8, j + 3, k + 0, Block.wood.blockID);
				world.setBlock(i + 8, j + 3, k + 1, Block.planks.blockID);
				world.setBlock(i + 8, j + 3, k + 2, Block.planks.blockID);
				world.setBlock(i + 8, j + 3, k + 3, Block.planks.blockID);
				world.setBlock(i + 8, j + 3, k + 4, Block.planks.blockID);
				world.setBlock(i + 8, j + 3, k + 5, Block.planks.blockID);
				world.setBlock(i + 8, j + 3, k + 6, Block.planks.blockID);
				world.setBlock(i + 8, j + 3, k + 7, Block.planks.blockID);
				world.setBlock(i + 8, j + 3, k + 8, Block.wood.blockID);
				world.setBlock(i + 8, j + 4, k + 0, Block.wood.blockID);
				world.setBlock(i + 8, j + 4, k + 1, Block.cobblestone.blockID);
				world.setBlock(i + 8, j + 3, k + 8, Block.cobblestone.blockID);
				world.setBlock(i + 8, j + 4, k + 2, Block.cobblestone.blockID);
				world.setBlock(i + 8, j + 4, k + 3, Block.cobblestone.blockID);
				world.setBlock(i + 8, j + 4, k + 4, Block.cobblestone.blockID);
				world.setBlock(i + 8, j + 4, k + 5, Block.cobblestone.blockID);
				world.setBlock(i + 8, j + 4, k + 6, Block.cobblestone.blockID);
				world.setBlock(i + 8, j + 4, k + 7, Block.cobblestone.blockID);
				world.setBlock(i + 8, j + 4, k + 8, Block.wood.blockID);
				world.setBlock(i + 8, j + 5, k + 0, 0);
				world.setBlock(i + 8, j + 5, k + 1, 0);
				world.setBlock(i + 8, j + 5, k + 2, 0);
				world.setBlock(i + 8, j + 5, k + 3, 0);
				world.setBlock(i + 8, j + 5, k + 4, 0);
				world.setBlock(i + 8, j + 5, k + 5, 0);
				world.setBlock(i + 8, j + 5, k + 6, 0);
				world.setBlock(i + 8, j + 5, k + 7, 0);
				world.setBlock(i + 8, j + 5, k + 8, 0);
				world.setBlock(i + 8, j + 6, k + 0, 0);
				world.setBlock(i + 8, j + 6, k + 1, 0);
				world.setBlock(i + 8, j + 6, k + 2, 0);
				world.setBlock(i + 8, j + 6, k + 3, 0);
				world.setBlock(i + 8, j + 6, k + 4, 0);
				world.setBlock(i + 8, j + 6, k + 5, 0);
				world.setBlock(i + 8, j + 6, k + 6, 0);
				world.setBlock(i + 8, j + 6, k + 7, 0);
				world.setBlock(i + 8, j + 6, k + 8, 0);

		}

		return true;
	}
}