package mods.polyblockz.common.blocks.constructions;

import ibxm.Player;

import java.util.Random;

import mods.polyblockz.common.PolyBlockz;
import mods.polyblockz.common.main.Block_Helper;
import mods.polyblockz.common.main.Item_Helper;
import net.minecraft.block.Block;
import net.minecraft.item.ItemStack;
import net.minecraft.util.WeightedRandomChestContent;
import net.minecraft.world.World;
import net.minecraft.world.gen.feature.WorldGenerator;
import net.minecraft.world.gen.structure.StructureBoundingBox;
import net.minecraftforge.common.ChestGenHooks;

public class BlokkHouse_poly extends WorldGenerator {

	public boolean generate(World world, Random par2Random, int i,
			int j, int k) {


		if (world.getBlockId(i, j, k) == Block_Helper.BlokkHouse_poly.blockID) {
			
			/*
			 * Blokk House
			 */
	
			 	world.setBlock(i + 4, j + 0, k + 6, 53);
			 	world.setBlock(i + 5, j + 1, k + 6, 53);
			 	world.setBlock(i + 6, j + 2, k + 6, 53);
			 	world.setBlock(i + 7, j + 3, k + 6, 53);

			 	world.setBlockToAir(i + 0, j + 0, k + 0);
	            world.setBlock(i + 0, j - 1, k + 7, 60);
	            world.setBlock(i + 0, j - 1, k + 6, 2);
	            world.setBlock(i + 0, j - 1, k + 2, 2);
	            world.setBlock(i + 0, j - 1, k + 1, 60);
	            world.setBlock(i + 1, j - 1, k + 7, 17);
	            world.setBlock(i + 1, j - 1, k + 6, 4);
	            world.setBlock(i + 1, j - 1, k + 5, 4);
	            world.setBlock(i + 1, j - 1, k + 4, 4);
	            world.setBlock(i + 1, j - 1, k + 3, 4);
	            world.setBlock(i + 1, j - 1, k + 2, 4);
	            world.setBlock(i + 1, j - 1, k + 1, 17);
	            world.setBlock(i + 2, j - 1, k + 7, 4);
	            world.setBlock(i + 2, j - 1, k + 6, 5);
	            world.setBlock(i + 2, j - 1, k + 5, 5);
	            world.setBlock(i + 2, j - 1, k + 4, 5);
	            world.setBlock(i + 2, j - 1, k + 3, 5);
	            world.setBlock(i + 2, j - 1, k + 2, 5);
	            world.setBlock(i + 2, j - 1, k + 1, 4);
	            world.setBlock(i + 3, j - 1, k + 7, 4);
	            world.setBlock(i + 3, j - 1, k + 6, 5);
	            world.setBlock(i + 3, j - 1, k + 5, 5);
	            world.setBlock(i + 3, j - 1, k + 4, 5);
	            world.setBlock(i + 3, j - 1, k + 3, 5);
	            world.setBlock(i + 3, j - 1, k + 2, 5);
	            world.setBlock(i + 3, j - 1, k + 1, 4);
	            world.setBlock(i + 3, j - 1, k + 0, 8);
	            world.setBlock(i + 4, j - 1, k + 7, 4);
	            world.setBlock(i + 4, j - 1, k + 6, 5);
	            world.setBlock(i + 4, j - 1, k + 5, 5);
	            world.setBlock(i + 4, j - 1, k + 4, 5);
	            world.setBlock(i + 4, j - 1, k + 3, 5);
	            world.setBlock(i + 4, j - 1, k + 2, 5);
	            world.setBlock(i + 4, j - 1, k + 1, 4);
	            world.setBlock(i + 4, j - 1, k + 0, 8);
	            world.setBlock(i + 5, j - 1, k + 7, 4);
	            world.setBlock(i + 5, j - 1, k + 6, 5);
	            world.setBlock(i + 5, j - 1, k + 5, 5);
	            world.setBlock(i + 5, j - 1, k + 4, 5);
	            world.setBlock(i + 5, j - 1, k + 3, 5);
	            world.setBlock(i + 5, j - 1, k + 2, 5);
	            world.setBlock(i + 5, j - 1, k + 1, 4);
	            world.setBlock(i + 5, j - 1, k + 0, 8);
	            world.setBlock(i + 6, j - 1, k + 7, 4);
	            world.setBlock(i + 6, j - 1, k + 6, 5);
	            world.setBlock(i + 6, j - 1, k + 5, 5);
	            world.setBlock(i + 6, j - 1, k + 4, 5);
	            world.setBlock(i + 6, j - 1, k + 3, 5);
	            world.setBlock(i + 6, j - 1, k + 2, 5);
	            world.setBlock(i + 6, j - 1, k + 1, 4);
	            world.setBlock(i + 7, j - 1, k + 7, 17);
	            world.setBlock(i + 7, j - 1, k + 6, 4);
	            world.setBlock(i + 7, j - 1, k + 5, 4);
	            world.setBlock(i + 7, j - 1, k + 4, 4);
	            world.setBlock(i + 7, j - 1, k + 3, 4);
	            world.setBlock(i + 7, j - 1, k + 2, 4);
	            world.setBlock(i + 7, j - 1, k + 1, 17);
	            world.setBlock(i + 0, j + 0, k + 7, 104);
	            world.setBlock(i + 0, j + 0, k + 6, 86);
	            world.setBlock(i + 0, j + 0, k + 2, 103);
	            world.setBlock(i + 0, j + 0, k + 1, 105);
	            world.setBlock(i + 1, j + 0, k + 7, 17);
	            world.setBlock(i + 1, j + 0, k + 6, 4);
	            world.setBlock(i + 1, j + 0, k + 5, 4);
	            world.setBlock(i + 1, j + 0, k + 3, 4);
	            world.setBlock(i + 1, j + 0, k + 2, 4);
	            world.setBlock(i + 1, j + 0, k + 1, 17);
	            world.setBlock(i + 2, j + 0, k + 7, 4);
	            world.setBlock(i + 2, j + 0, k + 2, 58);
	            world.setBlock(i + 2, j + 0, k + 1, 4);
	            world.setBlock(i + 3, j + 0, k + 7, 4);
	            world.setBlock(i + 3, j + 0, k + 1, 4);
	            world.setBlock(i + 4, j + 0, k + 7, 4);
	            world.setBlock(i + 4, j + 0, k + 1, 4);
	            world.setBlock(i + 5, j + 0, k + 7, 4);
	            world.setBlock(i + 5, j + 0, k + 1, 4);
	            world.setBlock(i + 5, j + 0, k + 7, 4);
	            world.setBlock(i + 5, j + 0, k + 6, 54);
	            world.setBlock(i + 6, j + 0, k + 6, 54);
	            world.setBlock(i + 6, j + 0, k + 7, 4);
	            world.setBlock(i + 6, j + 0, k + 3, 61);
	            world.setBlock(i + 6, j + 0, k + 2, 61);
	            world.setBlock(i + 6, j + 0, k + 1, 4);
	            world.setBlock(i + 7, j + 0, k + 7, 17);
	            world.setBlock(i + 7, j + 0, k + 6, 4);
	            world.setBlock(i + 7, j + 0, k + 5, 4);
	            world.setBlock(i + 7, j + 0, k + 4, 4);
	            world.setBlock(i + 7, j + 0, k + 3, 4);
	            world.setBlock(i + 7, j + 0, k + 2, 4);
	            world.setBlock(i + 7, j + 0, k + 1, 17);
	            world.setBlock(i + 1, j + 1, k + 7, 17);
	            world.setBlock(i + 1, j + 1, k + 6, 4);
	            world.setBlock(i + 1, j + 1, k + 5, 4);
	            world.setBlock(i + 1, j + 1, k + 3, 4);
	            world.setBlock(i + 1, j + 1, k + 2, 4);
	            world.setBlock(i + 1, j + 1, k + 1, 17);
	            world.setBlock(i + 2, j + 1, k + 7, 4);
	            world.setBlock(i + 2, j + 1, k + 1, 4);
	            
	            world.setBlock(i + 5, j + 1, k + 1, 20); //links
	            world.setBlock(i + 4, j + 1, k + 1, 20); //links
	            world.setBlock(i + 3, j + 1, k + 1, 20); //links
	            
	            world.setBlock(i + 4, j + 1, k + 7, 20); //rechts
	            world.setBlock(i + 5, j + 1, k + 7, 20);//rechts
	            world.setBlock(i + 3, j + 1, k + 7, 20);//rechts
	            
	            world.setBlock(i + 7, j + 1, k + 5, 20); //hinten
	            world.setBlock(i + 7, j + 1, k + 4, 20); //hinten
	            world.setBlock(i + 7, j + 1, k + 3, 20); //hinten
	            
	            world.setBlock(i + 6, j + 1, k + 7, 4);
	            world.setBlock(i + 6, j + 1, k + 1, 4);
	            world.setBlock(i + 7, j + 1, k + 7, 17);
	            world.setBlock(i + 7, j + 1, k + 6, 4);
	            world.setBlock(i + 7, j + 1, k + 2, 4);
	            world.setBlock(i + 7, j + 1, k + 1, 17);
	            world.setBlock(i + 0, j + 2, k + 8, 85);
	            world.setBlock(i + 0, j + 2, k + 7, 85);
	            world.setBlock(i + 0, j + 2, k + 1, 85);
	            world.setBlock(i + 0, j + 2, k + 0, 85);
	            world.setBlock(i + 1, j + 2, k + 8, 85);
	            world.setBlock(i + 1, j + 2, k + 7, 17);
	            world.setBlock(i + 1, j + 2, k + 6, 4);
	            world.setBlock(i + 1, j + 2, k + 5, 4);
	            world.setBlock(i + 1, j + 2, k + 4, 4);
	            world.setBlock(i + 1, j + 2, k + 3, 4);
	            world.setBlock(i + 1, j + 2, k + 2, 4);
	            world.setBlock(i + 1, j + 2, k + 1, 17);
	            world.setBlock(i + 1, j + 2, k + 0, 85);
	            world.setBlock(i + 2, j + 2, k + 7, 4);
	            world.setBlock(i + 2, j + 2, k + 1, 4);
	            world.setBlock(i + 3, j + 2, k + 7, 4);
	            world.setBlock(i + 3, j + 2, k + 1, 4);
	            world.setBlock(i + 4, j + 2, k + 7, 4);
	            world.setBlock(i + 4, j + 2, k + 1, 4);
	            world.setBlock(i + 5, j + 2, k + 7, 4);
	            world.setBlock(i + 5, j + 2, k + 1, 4);
	            world.setBlock(i + 6, j + 2, k + 7, 4);
	            world.setBlock(i + 6, j + 2, k + 1, 4);
	            world.setBlock(i + 7, j + 2, k + 8, 85);
	            world.setBlock(i + 7, j + 2, k + 7, 17);
	            world.setBlock(i + 7, j + 2, k + 6, 4);
	            world.setBlock(i + 7, j + 2, k + 5, 4);
	            world.setBlock(i + 7, j + 2, k + 4, 4);
	            world.setBlock(i + 7, j + 2, k + 3, 4);
	            world.setBlock(i + 7, j + 2, k + 2, 4);
	            world.setBlock(i + 7, j + 2, k + 1, 17);
	            world.setBlock(i + 7, j + 2, k + 0, 85);
	            world.setBlock(i + 8, j + 2, k + 8, 85);
	            world.setBlock(i + 8, j + 2, k + 7, 85);
	            world.setBlock(i + 8, j + 2, k + 1, 85);
	            world.setBlock(i + 8, j + 2, k + 0, 85);
	            world.setBlock(i + 0, j + 3, k + 8, 17);
	            world.setBlock(i + 0, j + 3, k + 7, 17);
	            world.setBlock(i + 0, j + 3, k + 6, 17);
	            world.setBlock(i + 0, j + 3, k + 5, 17);
	            world.setBlock(i + 0, j + 3, k + 4, 17);
	            world.setBlock(i + 0, j + 3, k + 3, 17);
	            world.setBlock(i + 0, j + 3, k + 2, 17);
	            world.setBlock(i + 0, j + 3, k + 1, 17);
	            world.setBlock(i + 0, j + 3, k + 0, 17);
	            world.setBlock(i + 1, j + 3, k + 8, 17);
	            world.setBlock(i + 1, j + 3, k + 7, 5);
	            world.setBlock(i + 1, j + 3, k + 6, 5);
	            world.setBlock(i + 1, j + 3, k + 5, 5);
	            world.setBlock(i + 1, j + 3, k + 4, 5);
	            world.setBlock(i + 1, j + 3, k + 3, 5);
	            world.setBlock(i + 1, j + 3, k + 2, 5);
	            world.setBlock(i + 1, j + 3, k + 1, 5);
	            world.setBlock(i + 1, j + 3, k + 0, 17);
	            world.setBlock(i + 2, j + 3, k + 8, 17);
	            world.setBlock(i + 2, j + 3, k + 7, 5);
	            world.setBlock(i + 2, j + 3, k + 6, 5);
	            world.setBlock(i + 2, j + 3, k + 5, 5);
	            world.setBlock(i + 2, j + 3, k + 4, 5);
	            world.setBlock(i + 2, j + 3, k + 3, 5);
	            world.setBlock(i + 2, j + 3, k + 2, 5);
	            world.setBlock(i + 2, j + 3, k + 1, 5);
	            world.setBlock(i + 2, j + 3, k + 0, 17);
	            world.setBlock(i + 3, j + 3, k + 8, 17);
	            world.setBlock(i + 3, j + 3, k + 7, 5);
	            world.setBlock(i + 3, j + 3, k + 6, 5);
	            world.setBlock(i + 3, j + 3, k + 5, 5);
	            world.setBlock(i + 3, j + 3, k + 4, 5);
	            world.setBlock(i + 3, j + 3, k + 3, 5);
	            world.setBlock(i + 3, j + 3, k + 2, 5);
	            world.setBlock(i + 3, j + 3, k + 1, 5);
	            world.setBlock(i + 3, j + 3, k + 0, 17);
	            world.setBlock(i + 4, j + 3, k + 8, 17);
	            world.setBlock(i + 4, j + 3, k + 7, 5);
	            world.setBlock(i + 4, j + 3, k + 5, 5);
	            world.setBlock(i + 4, j - 1, k + 4, 89);
	            world.setBlock(i + 4, j + 3, k + 4, 5);
	            world.setBlock(i + 4, j + 3, k + 3, 5);
	            world.setBlock(i + 4, j + 3, k + 2, 5);
	            world.setBlock(i + 4, j + 3, k + 1, 5);
	            world.setBlock(i + 4, j + 3, k + 0, 17);
	            world.setBlock(i + 5, j + 3, k + 8, 17);
	            world.setBlock(i + 5, j + 3, k + 7, 5);
	            world.setBlock(i + 5, j + 3, k + 5, 5);
	            world.setBlock(i + 5, j + 3, k + 4, 5);
	            world.setBlock(i + 5, j + 3, k + 3, 5);
	            world.setBlock(i + 5, j + 3, k + 2, 5);
	            world.setBlock(i + 5, j + 3, k + 1, 5);
	            world.setBlock(i + 5, j + 3, k + 0, 17);
	            world.setBlock(i + 6, j + 3, k + 8, 17);
	            world.setBlock(i + 6, j + 3, k + 7, 5);
	            world.setBlock(i + 6, j + 3, k + 5, 5);
	            world.setBlock(i + 6, j + 3, k + 4, 5);
	            world.setBlock(i + 6, j + 3, k + 3, 5);
	            world.setBlock(i + 6, j + 3, k + 2, 5);
	            world.setBlock(i + 6, j + 3, k + 1, 5);
	            world.setBlock(i + 6, j + 3, k + 0, 17);
	            world.setBlock(i + 7, j + 3, k + 8, 17);
	            world.setBlock(i + 7, j + 3, k + 7, 5);
	            world.setBlock(i + 7, j + 3, k + 5, 5);
	            world.setBlock(i + 7, j + 3, k + 4, 5);
	            world.setBlock(i + 7, j + 3, k + 3, 5);
	            world.setBlock(i + 7, j + 3, k + 2, 5);
	            world.setBlock(i + 7, j + 3, k + 1, 5);
	            world.setBlock(i + 7, j + 3, k + 0, 17);
	            world.setBlock(i + 8, j + 3, k + 8, 17);
	            world.setBlock(i + 8, j + 3, k + 7, 17);
	            world.setBlock(i + 8, j + 3, k + 6, 17);
	            world.setBlock(i + 8, j + 3, k + 5, 17);
	            world.setBlock(i + 8, j + 3, k + 4, 17);
	            world.setBlock(i + 8, j + 3, k + 3, 17);
	            world.setBlock(i + 8, j + 3, k + 2, 17);
	            world.setBlock(i + 8, j + 3, k + 1, 17);
	            world.setBlock(i + 8, j + 3, k + 0, 17);
	            world.setBlock(i + 0, j + 4, k + 8, 17);
	            world.setBlock(i + 0, j + 4, k + 7, 35);
	            world.setBlock(i + 0, j + 4, k + 6, 35);
	            world.setBlock(i + 0, j + 4, k + 5, 35);
	            world.setBlock(i + 0, j + 4, k + 4, 17);
	            world.setBlock(i + 0, j + 4, k + 3, 35);
	            world.setBlock(i + 0, j + 4, k + 2, 35);
	            world.setBlock(i + 0, j + 4, k + 1, 35);
	            world.setBlock(i + 0, j + 4, k + 0, 17);
	            world.setBlock(i + 1, j + 4, k + 8, 35);
	            world.setBlock(i + 1, j + 4, k + 0, 35);
	            world.setBlock(i + 2, j + 4, k + 8, 35);
	            world.setBlock(i + 2, j + 4, k + 0, 35);
	            world.setBlock(i + 3, j + 4, k + 8, 35);
	            world.setBlock(i + 3, j + 4, k + 0, 35);
	            world.setBlock(i + 4, j + 4, k + 8, 17);
	            world.setBlock(i + 4, j + 4, k + 0, 17);
	            world.setBlock(i + 5, j + 4, k + 8, 35);
	            world.setBlock(i + 5, j + 4, k + 0, 35);
	            world.setBlock(i + 6, j + 4, k + 8, 35);
	            world.setBlock(i + 6, j + 4, k + 0, 35);
	            world.setBlock(i + 7, j + 4, k + 8, 35);
	            world.setBlock(i + 7, j + 4, k + 0, 35);
	            world.setBlock(i + 8, j + 4, k + 8, 17);
	            world.setBlock(i + 8, j + 4, k + 7, 35);
	            world.setBlock(i + 8, j + 4, k + 6, 35);
	            world.setBlock(i + 8, j + 4, k + 5, 35);
	            world.setBlock(i + 8, j + 4, k + 4, 17);
	            world.setBlock(i + 8, j + 4, k + 3, 35);
	            world.setBlock(i + 8, j + 4, k + 2, 35);
	            world.setBlock(i + 8, j + 4, k + 1, 35);
	            world.setBlock(i + 8, j + 4, k + 0, 17);
	            world.setBlock(i + 0, j + 5, k + 8, 17);
	            world.setBlock(i + 0, j + 5, k + 7, 35);
	            world.setBlock(i + 0, j + 5, k + 6, 20);
	            world.setBlock(i + 0, j + 5, k + 5, 35);
	            world.setBlock(i + 0, j + 5, k + 4, 17);
	            world.setBlock(i + 0, j + 5, k + 3, 35);
	            world.setBlock(i + 0, j + 5, k + 2, 20);
	            world.setBlock(i + 0, j + 5, k + 1, 35);
	            world.setBlock(i + 0, j + 5, k + 0, 17);
	            world.setBlock(i + 1, j + 5, k + 8, 35);
	            world.setBlock(i + 1, j + 5, k + 0, 35);
	            world.setBlock(i + 2, j + 5, k + 8, 20);
	            world.setBlock(i + 2, j + 5, k + 0, 20);
	            world.setBlock(i + 3, j + 5, k + 8, 35);
	            world.setBlock(i + 3, j + 5, k + 0, 35);
	            world.setBlock(i + 4, j + 5, k + 8, 17);
	            world.setBlock(i + 4, j + 5, k + 0, 17);
	            world.setBlock(i + 5, j + 5, k + 8, 35);
	            world.setBlock(i + 5, j + 5, k + 0, 35);
	            world.setBlock(i + 6, j + 5, k + 8, 20);
	            world.setBlock(i + 6, j + 5, k + 0, 20);
	            world.setBlock(i + 7, j + 5, k + 8, 35);
	            world.setBlock(i + 7, j + 5, k + 0, 35);
	            world.setBlock(i + 8, j + 5, k + 8, 17);
	            world.setBlock(i + 8, j + 5, k + 7, 35);
	            world.setBlock(i + 8, j + 5, k + 6, 20);
	            world.setBlock(i + 8, j + 5, k + 5, 35);
	            world.setBlock(i + 8, j + 5, k + 4, 17);
	            world.setBlock(i + 8, j + 5, k + 3, 35);
	            world.setBlock(i + 8, j + 5, k + 2, 20);
	            world.setBlock(i + 8, j + 5, k + 1, 35);
	            world.setBlock(i + 8, j + 5, k + 0, 17);
	            world.setBlock(i + 0, j + 6, k + 8, 17);
	            world.setBlock(i + 0, j + 6, k + 7, 35);
	            world.setBlock(i + 0, j + 6, k + 6, 35);
	            world.setBlock(i + 0, j + 6, k + 5, 35);
	            world.setBlock(i + 0, j + 6, k + 4, 17);
	            world.setBlock(i + 0, j + 6, k + 3, 35);
	            world.setBlock(i + 0, j + 6, k + 2, 35);
	            world.setBlock(i + 0, j + 6, k + 1, 35);
	            world.setBlock(i + 0, j + 6, k + 0, 17);
	            world.setBlock(i + 1, j + 6, k + 8, 35);
	            world.setBlock(i + 1, j + 6, k + 0, 35);
	            world.setBlock(i + 2, j + 6, k + 8, 35);
	            world.setBlock(i + 2, j + 6, k + 0, 35);
	            world.setBlock(i + 3, j + 6, k + 8, 35);
	            world.setBlock(i + 3, j + 6, k + 0, 35);
	            world.setBlock(i + 4, j + 6, k + 8, 17);
	            world.setBlock(i + 4, j + 6, k + 0, 17);
	            world.setBlock(i + 5, j + 6, k + 8, 35);
	            world.setBlock(i + 5, j + 6, k + 0, 35);
	            world.setBlock(i + 6, j + 6, k + 8, 35);
	            world.setBlock(i + 6, j + 6, k + 0, 35);
	            world.setBlock(i + 7, j + 6, k + 8, 35);
	            world.setBlock(i + 7, j + 6, k + 0, 35);
	            world.setBlock(i + 8, j + 6, k + 8, 17);
	            world.setBlock(i + 8, j + 6, k + 7, 35);
	            world.setBlock(i + 8, j + 6, k + 6, 35);
	            world.setBlock(i + 8, j + 6, k + 5, 35);
	            world.setBlock(i + 8, j + 6, k + 4, 17);
	            world.setBlock(i + 8, j + 6, k + 3, 35);
	            world.setBlock(i + 8, j + 6, k + 2, 35);
	            world.setBlock(i + 8, j + 6, k + 1, 35);
	            world.setBlock(i + 8, j + 6, k + 0, 17);
	            world.setBlock(i + 0, j + 7, k + 8, 17);
	            world.setBlock(i + 0, j + 7, k + 7, 17);
	            world.setBlock(i + 0, j + 7, k + 6, 17);
	            world.setBlock(i + 0, j + 7, k + 5, 17);
	            world.setBlock(i + 0, j + 7, k + 4, 17);
	            world.setBlock(i + 0, j + 7, k + 3, 17);
	            world.setBlock(i + 0, j + 7, k + 2, 17);
	            world.setBlock(i + 0, j + 7, k + 1, 17);
	            world.setBlock(i + 0, j + 7, k + 0, 17);
	            world.setBlock(i + 1, j + 7, k + 8, 17);
	            world.setBlock(i + 1, j + 7, k + 0, 17);
	            world.setBlock(i + 2, j + 7, k + 8, 17);
	            world.setBlock(i + 2, j + 7, k + 0, 17);
	            world.setBlock(i + 3, j + 7, k + 8, 17);
	            world.setBlock(i + 3, j + 7, k + 0, 17);
	            world.setBlock(i + 4, j + 7, k + 8, 17);
	            world.setBlock(i + 4, j + 7, k + 0, 17);
	            world.setBlock(i + 5, j + 7, k + 8, 17);
	            world.setBlock(i + 5, j + 7, k + 0, 17);
	            world.setBlock(i + 6, j + 7, k + 8, 17);
	            world.setBlock(i + 6, j + 7, k + 0, 17);
	            world.setBlock(i + 7, j + 7, k + 8, 17);
	            world.setBlock(i + 7, j + 7, k + 0, 17);
	            world.setBlock(i + 8, j + 7, k + 8, 17);
	            world.setBlock(i + 8, j + 7, k + 7, 17);
	            world.setBlock(i + 8, j + 7, k + 6, 17);
	            world.setBlock(i + 8, j + 7, k + 5, 17);
	            world.setBlock(i + 8, j + 7, k + 4, 17);
	            world.setBlock(i + 8, j + 7, k + 3, 17);
	            world.setBlock(i + 8, j + 7, k + 2, 17);
	            world.setBlock(i + 8, j + 7, k + 1, 17);
	            world.setBlock(i + 8, j + 7, k + 0, 17);
	            world.setBlock(i + 1, j + 8, k + 7, 17);
	            world.setBlock(i + 1, j + 8, k + 6, 17);
	            world.setBlock(i + 1, j + 8, k + 5, 17);
	            world.setBlock(i + 1, j + 8, k + 4, 17);
	            world.setBlock(i + 1, j + 8, k + 3, 17);
	            world.setBlock(i + 1, j + 8, k + 2, 17);
	            world.setBlock(i + 1, j + 8, k + 1, 17);
	            world.setBlock(i + 2, j + 8, k + 7, 17);
	            world.setBlock(i + 2, j + 8, k + 6, 35);
	            world.setBlock(i + 2, j + 8, k + 5, 35);
	            world.setBlock(i + 2, j + 8, k + 4, 17);
	            world.setBlock(i + 2, j + 8, k + 3, 35);
	            world.setBlock(i + 2, j + 8, k + 2, 35);
	            world.setBlock(i + 2, j + 8, k + 1, 17);
	            world.setBlock(i + 3, j + 8, k + 7, 17);
	            world.setBlock(i + 3, j + 8, k + 6, 35);
	            world.setBlock(i + 3, j + 8, k + 5, 35);
	            world.setBlock(i + 3, j + 8, k + 4, 17);
	            world.setBlock(i + 3, j + 8, k + 3, 35);
	            world.setBlock(i + 3, j + 8, k + 2, 35);
	            world.setBlock(i + 3, j + 8, k + 1, 17);
	            world.setBlock(i + 4, j + 8, k + 7, 17);
	            world.setBlock(i + 4, j + 8, k + 6, 17);
	            world.setBlock(i + 4, j + 8, k + 5, 17);
	            world.setBlock(i + 4, j + 8, k + 4, 17);
	            world.setBlock(i + 4, j + 8, k + 3, 17);
	            world.setBlock(i + 4, j + 8, k + 2, 17);
	            world.setBlock(i + 4, j + 8, k + 1, 17);
	            world.setBlock(i + 5, j + 8, k + 7, 17);
	            world.setBlock(i + 5, j + 8, k + 6, 35);
	            world.setBlock(i + 5, j + 8, k + 5, 35);
	            world.setBlock(i + 5, j + 8, k + 4, 17);
	            world.setBlock(i + 5, j + 8, k + 3, 35);
	            world.setBlock(i + 5, j + 8, k + 2, 35);
	            world.setBlock(i + 5, j + 8, k + 1, 17);
	            world.setBlock(i + 6, j + 8, k + 7, 17);
	            world.setBlock(i + 6, j + 8, k + 6, 35);
	            world.setBlock(i + 6, j + 8, k + 5, 35);
	            world.setBlock(i + 6, j + 8, k + 4, 17);
	            world.setBlock(i + 6, j + 8, k + 3, 35);
	            world.setBlock(i + 6, j + 8, k + 2, 35);
	            world.setBlock(i + 6, j + 8, k + 1, 17);
	            world.setBlock(i + 7, j + 8, k + 7, 17);
	            world.setBlock(i + 7, j + 8, k + 6, 17);
	            world.setBlock(i + 7, j + 8, k + 5, 17);
	            world.setBlock(i + 7, j + 8, k + 4, 17);
	            world.setBlock(i + 7, j + 8, k + 3, 17);
	            world.setBlock(i + 7, j + 8, k + 2, 17);
	            world.setBlock(i + 7, j + 8, k + 1, 17);
	            world.setBlock(i + 2, j + 9, k + 6, 17);
	            world.setBlock(i + 2, j + 9, k + 5, 17);
	            world.setBlock(i + 2, j + 9, k + 4, 17);
	            world.setBlock(i + 2, j + 9, k + 3, 17);
	            world.setBlock(i + 2, j + 9, k + 2, 17);
	            world.setBlock(i + 3, j + 9, k + 6, 17);
	            world.setBlock(i + 3, j + 9, k + 2, 17);
	            world.setBlock(i + 4, j + 9, k + 6, 17);
	            world.setBlock(i + 4, j + 9, k + 2, 17);
	            world.setBlock(i + 5, j + 9, k + 6, 17);
	            world.setBlock(i + 5, j + 9, k + 2, 17);
	            world.setBlock(i + 6, j + 9, k + 6, 17);
	            world.setBlock(i + 6, j + 9, k + 5, 17);
	            world.setBlock(i + 6, j + 9, k + 4, 17);
	            world.setBlock(i + 6, j + 9, k + 3, 17);
	            world.setBlock(i + 6, j + 9, k + 2, 17);
	            world.setBlock(i + 3, j + 10, k + 5, 17);
	            world.setBlock(i + 3, j + 10, k + 4, 17);
	            world.setBlock(i + 3, j + 10, k + 3, 17);
	            world.setBlock(i + 4, j + 10, k + 5, 17);
	            world.setBlock(i + 4, j + 10, k + 4, 89);
	            world.setBlock(i + 4, j + 10, k + 3, 17);
	            world.setBlock(i + 5, j + 10, k + 5, 17);
	            world.setBlock(i + 5, j + 10, k + 4, 17);
	            world.setBlock(i + 5, j + 10, k + 3, 17);
	            world.setBlock(i + 4, j + 11, k + 4, 17);

		}

		return true;
	}

	
        
}